[Wed Nov 02 22:32:02.123110 2016] [wsgi:error] [pid 2033:tid 139625821628160] [client 71.42.119.84:63396] mod_wsgi (pid=2033): Target WSGI script '/var/www/cs373f-idb/app.wsgi' cannot be loaded as Python module.
[Wed Nov 02 22:32:02.123308 2016] [wsgi:error] [pid 2033:tid 139625821628160] [client 71.42.119.84:63396] mod_wsgi (pid=2033): Exception occurred processing WSGI script '/var/www/cs373f-idb/app.wsgi'.
[Wed Nov 02 22:32:02.132296 2016] [wsgi:error] [pid 2033:tid 139625821628160] [client 71.42.119.84:63396] Traceback (most recent call last):
[Wed Nov 02 22:32:02.132444 2016] [wsgi:error] [pid 2033:tid 139625821628160] [client 71.42.119.84:63396]   File "/var/www/cs373f-idb/app.wsgi", line 7, in <module>
[Wed Nov 02 22:32:02.132468 2016] [wsgi:error] [pid 2033:tid 139625821628160] [client 71.42.119.84:63396]     from app.app import app as application
[Wed Nov 02 22:32:02.132499 2016] [wsgi:error] [pid 2033:tid 139625821628160] [client 71.42.119.84:63396]   File "/var/www/cs373f-idb/app/app.py", line 8, in <module>
[Wed Nov 02 22:32:02.132513 2016] [wsgi:error] [pid 2033:tid 139625821628160] [client 71.42.119.84:63396]     import models
[Wed Nov 02 22:32:02.132572 2016] [wsgi:error] [pid 2033:tid 139625821628160] [client 71.42.119.84:63396] ImportError: No module named 'models'
[Wed Nov 02 22:32:02.445450 2016] [wsgi:error] [pid 2034:tid 139625712523008] [client 71.42.119.84:63399] mod_wsgi (pid=2034): Target WSGI script '/var/www/cs373f-idb/app.wsgi' cannot be loaded as Python module.
[Wed Nov 02 22:32:02.445588 2016] [wsgi:error] [pid 2034:tid 139625712523008] [client 71.42.119.84:63399] mod_wsgi (pid=2034): Exception occurred processing WSGI script '/var/www/cs373f-idb/app.wsgi'.
[Wed Nov 02 22:32:02.446360 2016] [wsgi:error] [pid 2034:tid 139625712523008] [client 71.42.119.84:63399] Traceback (most recent call last):
[Wed Nov 02 22:32:02.446431 2016] [wsgi:error] [pid 2034:tid 139625712523008] [client 71.42.119.84:63399]   File "/var/www/cs373f-idb/app.wsgi", line 7, in <module>
[Wed Nov 02 22:32:02.446460 2016] [wsgi:error] [pid 2034:tid 139625712523008] [client 71.42.119.84:63399]     from app.app import app as application
[Wed Nov 02 22:32:02.446478 2016] [wsgi:error] [pid 2034:tid 139625712523008] [client 71.42.119.84:63399]   File "/var/www/cs373f-idb/app/app.py", line 8, in <module>
[Wed Nov 02 22:32:02.446487 2016] [wsgi:error] [pid 2034:tid 139625712523008] [client 71.42.119.84:63399]     import models
[Wed Nov 02 22:32:02.446543 2016] [wsgi:error] [pid 2034:tid 139625712523008] [client 71.42.119.84:63399] ImportError: No module named 'models'
[Wed Nov 02 23:00:29.563121 2016] [wsgi:error] [pid 2935:tid 140385636579072] [client 71.42.119.84:63749] mod_wsgi (pid=2935): Target WSGI script '/var/www/cs373f-idb/app.wsgi' cannot be loaded as Python module.
[Wed Nov 02 23:00:29.563324 2016] [wsgi:error] [pid 2935:tid 140385636579072] [client 71.42.119.84:63749] mod_wsgi (pid=2935): Exception occurred processing WSGI script '/var/www/cs373f-idb/app.wsgi'.
[Wed Nov 02 23:00:29.564336 2016] [wsgi:error] [pid 2935:tid 140385636579072] [client 71.42.119.84:63749] Traceback (most recent call last):
[Wed Nov 02 23:00:29.564391 2016] [wsgi:error] [pid 2935:tid 140385636579072] [client 71.42.119.84:63749]   File "/var/www/cs373f-idb/app.wsgi", line 7, in <module>
[Wed Nov 02 23:00:29.564403 2016] [wsgi:error] [pid 2935:tid 140385636579072] [client 71.42.119.84:63749]     from app.app import app as application
[Wed Nov 02 23:00:29.564419 2016] [wsgi:error] [pid 2935:tid 140385636579072] [client 71.42.119.84:63749]   File "/var/www/cs373f-idb/app/app.py", line 8, in <module>
[Wed Nov 02 23:00:29.564427 2016] [wsgi:error] [pid 2935:tid 140385636579072] [client 71.42.119.84:63749]     import models
[Wed Nov 02 23:00:29.564464 2016] [wsgi:error] [pid 2935:tid 140385636579072] [client 71.42.119.84:63749] ImportError: No module named 'models'
[Thu Nov 03 00:08:41.990225 2016] [wsgi:error] [pid 4319:tid 140183898941184] [client 71.42.119.84:63610] mod_wsgi (pid=4319): Target WSGI script '/var/www/cs373f-idb/app.wsgi' cannot be loaded as Python module.
[Thu Nov 03 00:08:41.990393 2016] [wsgi:error] [pid 4319:tid 140183898941184] [client 71.42.119.84:63610] mod_wsgi (pid=4319): Exception occurred processing WSGI script '/var/www/cs373f-idb/app.wsgi'.
[Thu Nov 03 00:08:41.991035 2016] [wsgi:error] [pid 4319:tid 140183898941184] [client 71.42.119.84:63610] Traceback (most recent call last):
[Thu Nov 03 00:08:41.991086 2016] [wsgi:error] [pid 4319:tid 140183898941184] [client 71.42.119.84:63610]   File "/var/www/cs373f-idb/app.wsgi", line 7, in <module>
[Thu Nov 03 00:08:41.991097 2016] [wsgi:error] [pid 4319:tid 140183898941184] [client 71.42.119.84:63610]     from app.app import app as application
[Thu Nov 03 00:08:41.991112 2016] [wsgi:error] [pid 4319:tid 140183898941184] [client 71.42.119.84:63610]   File "/var/www/cs373f-idb/app/app.py", line 8, in <module>
[Thu Nov 03 00:08:41.991119 2016] [wsgi:error] [pid 4319:tid 140183898941184] [client 71.42.119.84:63610]     import models
[Thu Nov 03 00:08:41.991153 2016] [wsgi:error] [pid 4319:tid 140183898941184] [client 71.42.119.84:63610] ImportError: No module named 'models'
[Thu Nov 03 00:18:42.424981 2016] [wsgi:error] [pid 4485:tid 140443934906112] [client 71.42.119.84:63660] mod_wsgi (pid=4485): Target WSGI script '/var/www/cs373f-idb/app.wsgi' cannot be loaded as Python module.
[Thu Nov 03 00:18:42.425106 2016] [wsgi:error] [pid 4485:tid 140443934906112] [client 71.42.119.84:63660] mod_wsgi (pid=4485): Exception occurred processing WSGI script '/var/www/cs373f-idb/app.wsgi'.
[Thu Nov 03 00:18:42.425494 2016] [wsgi:error] [pid 4485:tid 140443934906112] [client 71.42.119.84:63660] Traceback (most recent call last):
[Thu Nov 03 00:18:42.425541 2016] [wsgi:error] [pid 4485:tid 140443934906112] [client 71.42.119.84:63660]   File "/var/www/cs373f-idb/app.wsgi", line 7, in <module>
[Thu Nov 03 00:18:42.425552 2016] [wsgi:error] [pid 4485:tid 140443934906112] [client 71.42.119.84:63660]     from app.app import app as application
[Thu Nov 03 00:18:42.425581 2016] [wsgi:error] [pid 4485:tid 140443934906112] [client 71.42.119.84:63660]   File "/var/www/cs373f-idb/app/app.py", line 8
[Thu Nov 03 00:18:42.425603 2016] [wsgi:error] [pid 4485:tid 140443934906112] [client 71.42.119.84:63660]     import app/models
[Thu Nov 03 00:18:42.425638 2016] [wsgi:error] [pid 4485:tid 140443934906112] [client 71.42.119.84:63660]               ^
[Thu Nov 03 00:18:42.425659 2016] [wsgi:error] [pid 4485:tid 140443934906112] [client 71.42.119.84:63660] SyntaxError: invalid syntax
[Thu Nov 03 00:18:42.828931 2016] [wsgi:error] [pid 4486:tid 140443752822528] [client 71.42.119.84:63666] mod_wsgi (pid=4486): Target WSGI script '/var/www/cs373f-idb/app.wsgi' cannot be loaded as Python module.
[Thu Nov 03 00:18:42.829080 2016] [wsgi:error] [pid 4486:tid 140443752822528] [client 71.42.119.84:63666] mod_wsgi (pid=4486): Exception occurred processing WSGI script '/var/www/cs373f-idb/app.wsgi'.
[Thu Nov 03 00:18:42.829538 2016] [wsgi:error] [pid 4486:tid 140443752822528] [client 71.42.119.84:63666] Traceback (most recent call last):
[Thu Nov 03 00:18:42.829589 2016] [wsgi:error] [pid 4486:tid 140443752822528] [client 71.42.119.84:63666]   File "/var/www/cs373f-idb/app.wsgi", line 7, in <module>
[Thu Nov 03 00:18:42.829600 2016] [wsgi:error] [pid 4486:tid 140443752822528] [client 71.42.119.84:63666]     from app.app import app as application
[Thu Nov 03 00:18:42.829629 2016] [wsgi:error] [pid 4486:tid 140443752822528] [client 71.42.119.84:63666]   File "/var/www/cs373f-idb/app/app.py", line 8
[Thu Nov 03 00:18:42.829655 2016] [wsgi:error] [pid 4486:tid 140443752822528] [client 71.42.119.84:63666]     import app/models
[Thu Nov 03 00:18:42.829691 2016] [wsgi:error] [pid 4486:tid 140443752822528] [client 71.42.119.84:63666]               ^
[Thu Nov 03 00:18:42.829713 2016] [wsgi:error] [pid 4486:tid 140443752822528] [client 71.42.119.84:63666] SyntaxError: invalid syntax
[Thu Nov 03 03:42:45.718097 2016] [wsgi:error] [pid 5953:tid 140141964261120] [client 71.42.119.84:64022] mod_wsgi (pid=5953): Target WSGI script '/var/www/cs373f-idb/app.wsgi' cannot be loaded as Python module.
[Thu Nov 03 03:42:45.719095 2016] [wsgi:error] [pid 5953:tid 140141964261120] [client 71.42.119.84:64022] mod_wsgi (pid=5953): Exception occurred processing WSGI script '/var/www/cs373f-idb/app.wsgi'.
[Thu Nov 03 03:42:45.720887 2016] [wsgi:error] [pid 5953:tid 140141964261120] [client 71.42.119.84:64022] Traceback (most recent call last):
[Thu Nov 03 03:42:45.721008 2016] [wsgi:error] [pid 5953:tid 140141964261120] [client 71.42.119.84:64022]   File "/var/www/cs373f-idb/app.wsgi", line 7, in <module>
[Thu Nov 03 03:42:45.721029 2016] [wsgi:error] [pid 5953:tid 140141964261120] [client 71.42.119.84:64022]     from app.app import app as application
[Thu Nov 03 03:42:45.721054 2016] [wsgi:error] [pid 5953:tid 140141964261120] [client 71.42.119.84:64022]   File "/var/www/cs373f-idb/app/app.py", line 9, in <module>
[Thu Nov 03 03:42:45.721068 2016] [wsgi:error] [pid 5953:tid 140141964261120] [client 71.42.119.84:64022]     import models
[Thu Nov 03 03:42:45.721133 2016] [wsgi:error] [pid 5953:tid 140141964261120] [client 71.42.119.84:64022] ImportError: No module named 'models'
[Thu Nov 03 03:43:02.808022 2016] [wsgi:error] [pid 5953:tid 140141989439232] [client 71.42.119.84:62944] mod_wsgi (pid=5953): Target WSGI script '/var/www/cs373f-idb/app.wsgi' cannot be loaded as Python module.
[Thu Nov 03 03:43:02.808139 2016] [wsgi:error] [pid 5953:tid 140141989439232] [client 71.42.119.84:62944] mod_wsgi (pid=5953): Exception occurred processing WSGI script '/var/www/cs373f-idb/app.wsgi'.
[Thu Nov 03 03:43:02.808393 2016] [wsgi:error] [pid 5953:tid 140141989439232] [client 71.42.119.84:62944] Traceback (most recent call last):
[Thu Nov 03 03:43:02.808457 2016] [wsgi:error] [pid 5953:tid 140141989439232] [client 71.42.119.84:62944]   File "/var/www/cs373f-idb/app.wsgi", line 7, in <module>
[Thu Nov 03 03:43:02.808471 2016] [wsgi:error] [pid 5953:tid 140141989439232] [client 71.42.119.84:62944]     from app.app import app as application
[Thu Nov 03 03:43:02.808487 2016] [wsgi:error] [pid 5953:tid 140141989439232] [client 71.42.119.84:62944]   File "/var/www/cs373f-idb/app/app.py", line 9, in <module>
[Thu Nov 03 03:43:02.808495 2016] [wsgi:error] [pid 5953:tid 140141989439232] [client 71.42.119.84:62944]     import models
[Thu Nov 03 03:43:02.808527 2016] [wsgi:error] [pid 5953:tid 140141989439232] [client 71.42.119.84:62944] ImportError: No module named 'models'
[Thu Nov 03 03:44:04.105500 2016] [wsgi:error] [pid 5953:tid 140141997831936] [client 71.42.119.84:63190] mod_wsgi (pid=5953): Target WSGI script '/var/www/cs373f-idb/app.wsgi' cannot be loaded as Python module.
[Thu Nov 03 03:44:04.105780 2016] [wsgi:error] [pid 5953:tid 140141997831936] [client 71.42.119.84:63190] mod_wsgi (pid=5953): Exception occurred processing WSGI script '/var/www/cs373f-idb/app.wsgi'.
[Thu Nov 03 03:44:04.106180 2016] [wsgi:error] [pid 5953:tid 140141997831936] [client 71.42.119.84:63190] Traceback (most recent call last):
[Thu Nov 03 03:44:04.106232 2016] [wsgi:error] [pid 5953:tid 140141997831936] [client 71.42.119.84:63190]   File "/var/www/cs373f-idb/app.wsgi", line 7, in <module>
[Thu Nov 03 03:44:04.106244 2016] [wsgi:error] [pid 5953:tid 140141997831936] [client 71.42.119.84:63190]     from app.app import app as application
[Thu Nov 03 03:44:04.106259 2016] [wsgi:error] [pid 5953:tid 140141997831936] [client 71.42.119.84:63190]   File "/var/www/cs373f-idb/app/app.py", line 9, in <module>
[Thu Nov 03 03:44:04.106267 2016] [wsgi:error] [pid 5953:tid 140141997831936] [client 71.42.119.84:63190]     import models
[Thu Nov 03 03:44:04.106312 2016] [wsgi:error] [pid 5953:tid 140141997831936] [client 71.42.119.84:63190] ImportError: No module named 'models'
[Thu Nov 03 03:44:06.195252 2016] [wsgi:error] [pid 5953:tid 140141981046528] [client 71.42.119.84:63264] mod_wsgi (pid=5953): Target WSGI script '/var/www/cs373f-idb/app.wsgi' cannot be loaded as Python module.
[Thu Nov 03 03:44:06.195374 2016] [wsgi:error] [pid 5953:tid 140141981046528] [client 71.42.119.84:63264] mod_wsgi (pid=5953): Exception occurred processing WSGI script '/var/www/cs373f-idb/app.wsgi'.
[Thu Nov 03 03:44:06.195557 2016] [wsgi:error] [pid 5953:tid 140141981046528] [client 71.42.119.84:63264] Traceback (most recent call last):
[Thu Nov 03 03:44:06.195650 2016] [wsgi:error] [pid 5953:tid 140141981046528] [client 71.42.119.84:63264]   File "/var/www/cs373f-idb/app.wsgi", line 7, in <module>
[Thu Nov 03 03:44:06.195663 2016] [wsgi:error] [pid 5953:tid 140141981046528] [client 71.42.119.84:63264]     from app.app import app as application
[Thu Nov 03 03:44:06.195679 2016] [wsgi:error] [pid 5953:tid 140141981046528] [client 71.42.119.84:63264]   File "/var/www/cs373f-idb/app/app.py", line 9, in <module>
[Thu Nov 03 03:44:06.195686 2016] [wsgi:error] [pid 5953:tid 140141981046528] [client 71.42.119.84:63264]     import models
[Thu Nov 03 03:44:06.195718 2016] [wsgi:error] [pid 5953:tid 140141981046528] [client 71.42.119.84:63264] ImportError: No module named 'models'
[Thu Nov 03 03:45:19.079534 2016] [wsgi:error] [pid 5953:tid 140141947475712] [client 71.42.119.84:63566] mod_wsgi (pid=5953): Target WSGI script '/var/www/cs373f-idb/app.wsgi' cannot be loaded as Python module.
[Thu Nov 03 03:45:19.079687 2016] [wsgi:error] [pid 5953:tid 140141947475712] [client 71.42.119.84:63566] mod_wsgi (pid=5953): Exception occurred processing WSGI script '/var/www/cs373f-idb/app.wsgi'.
[Thu Nov 03 03:45:19.079886 2016] [wsgi:error] [pid 5953:tid 140141947475712] [client 71.42.119.84:63566] Traceback (most recent call last):
[Thu Nov 03 03:45:19.080005 2016] [wsgi:error] [pid 5953:tid 140141947475712] [client 71.42.119.84:63566]   File "/var/www/cs373f-idb/app.wsgi", line 7, in <module>
[Thu Nov 03 03:45:19.080017 2016] [wsgi:error] [pid 5953:tid 140141947475712] [client 71.42.119.84:63566]     from app.app import app as application
[Thu Nov 03 03:45:19.080032 2016] [wsgi:error] [pid 5953:tid 140141947475712] [client 71.42.119.84:63566]   File "/var/www/cs373f-idb/app/app.py", line 9, in <module>
[Thu Nov 03 03:45:19.080040 2016] [wsgi:error] [pid 5953:tid 140141947475712] [client 71.42.119.84:63566]     import models
[Thu Nov 03 03:45:19.080122 2016] [wsgi:error] [pid 5953:tid 140141947475712] [client 71.42.119.84:63566] ImportError: No module named 'models'
[Thu Nov 03 03:45:31.613023 2016] [wsgi:error] [pid 5953:tid 140141972653824] [client 71.42.119.84:64002] mod_wsgi (pid=5953): Target WSGI script '/var/www/cs373f-idb/app.wsgi' cannot be loaded as Python module.
[Thu Nov 03 03:45:31.613224 2016] [wsgi:error] [pid 5953:tid 140141972653824] [client 71.42.119.84:64002] mod_wsgi (pid=5953): Exception occurred processing WSGI script '/var/www/cs373f-idb/app.wsgi'.
[Thu Nov 03 03:45:31.613522 2016] [wsgi:error] [pid 5953:tid 140141972653824] [client 71.42.119.84:64002] Traceback (most recent call last):
[Thu Nov 03 03:45:31.613611 2016] [wsgi:error] [pid 5953:tid 140141972653824] [client 71.42.119.84:64002]   File "/var/www/cs373f-idb/app.wsgi", line 7, in <module>
[Thu Nov 03 03:45:31.613634 2016] [wsgi:error] [pid 5953:tid 140141972653824] [client 71.42.119.84:64002]     from app.app import app as application
[Thu Nov 03 03:45:31.613673 2016] [wsgi:error] [pid 5953:tid 140141972653824] [client 71.42.119.84:64002]   File "/var/www/cs373f-idb/app/app.py", line 9, in <module>
[Thu Nov 03 03:45:31.613691 2016] [wsgi:error] [pid 5953:tid 140141972653824] [client 71.42.119.84:64002]     import models
[Thu Nov 03 03:45:31.613759 2016] [wsgi:error] [pid 5953:tid 140141972653824] [client 71.42.119.84:64002] ImportError: No module named 'models'
[Thu Nov 03 03:45:38.679580 2016] [wsgi:error] [pid 5953:tid 140142129039104] [client 71.42.119.84:64001] mod_wsgi (pid=5953): Target WSGI script '/var/www/cs373f-idb/app.wsgi' cannot be loaded as Python module.
[Thu Nov 03 03:45:38.679798 2016] [wsgi:error] [pid 5953:tid 140142129039104] [client 71.42.119.84:64001] mod_wsgi (pid=5953): Exception occurred processing WSGI script '/var/www/cs373f-idb/app.wsgi'.
[Thu Nov 03 03:45:38.680007 2016] [wsgi:error] [pid 5953:tid 140142129039104] [client 71.42.119.84:64001] Traceback (most recent call last):
[Thu Nov 03 03:45:38.680080 2016] [wsgi:error] [pid 5953:tid 140142129039104] [client 71.42.119.84:64001]   File "/var/www/cs373f-idb/app.wsgi", line 7, in <module>
[Thu Nov 03 03:45:38.680092 2016] [wsgi:error] [pid 5953:tid 140142129039104] [client 71.42.119.84:64001]     from app.app import app as application
[Thu Nov 03 03:45:38.680107 2016] [wsgi:error] [pid 5953:tid 140142129039104] [client 71.42.119.84:64001]   File "/var/www/cs373f-idb/app/app.py", line 9, in <module>
[Thu Nov 03 03:45:38.680115 2016] [wsgi:error] [pid 5953:tid 140142129039104] [client 71.42.119.84:64001]     import models
[Thu Nov 03 03:45:38.680146 2016] [wsgi:error] [pid 5953:tid 140142129039104] [client 71.42.119.84:64001] ImportError: No module named 'models'
[Thu Nov 03 03:46:21.296566 2016] [wsgi:error] [pid 5953:tid 140142120646400] [client 71.42.119.84:63625] mod_wsgi (pid=5953): Target WSGI script '/var/www/cs373f-idb/app.wsgi' cannot be loaded as Python module.
[Thu Nov 03 03:46:21.296676 2016] [wsgi:error] [pid 5953:tid 140142120646400] [client 71.42.119.84:63625] mod_wsgi (pid=5953): Exception occurred processing WSGI script '/var/www/cs373f-idb/app.wsgi'.
[Thu Nov 03 03:46:21.296841 2016] [wsgi:error] [pid 5953:tid 140142120646400] [client 71.42.119.84:63625] Traceback (most recent call last):
[Thu Nov 03 03:46:21.296889 2016] [wsgi:error] [pid 5953:tid 140142120646400] [client 71.42.119.84:63625]   File "/var/www/cs373f-idb/app.wsgi", line 7, in <module>
[Thu Nov 03 03:46:21.296901 2016] [wsgi:error] [pid 5953:tid 140142120646400] [client 71.42.119.84:63625]     from app.app import app as application
[Thu Nov 03 03:46:21.296916 2016] [wsgi:error] [pid 5953:tid 140142120646400] [client 71.42.119.84:63625]   File "/var/www/cs373f-idb/app/app.py", line 9, in <module>
[Thu Nov 03 03:46:21.296924 2016] [wsgi:error] [pid 5953:tid 140142120646400] [client 71.42.119.84:63625]     import models
[Thu Nov 03 03:46:21.296956 2016] [wsgi:error] [pid 5953:tid 140142120646400] [client 71.42.119.84:63625] ImportError: No module named 'models'
[Thu Nov 03 03:46:24.640216 2016] [wsgi:error] [pid 5953:tid 140142112253696] [client 71.42.119.84:63628] mod_wsgi (pid=5953): Target WSGI script '/var/www/cs373f-idb/app.wsgi' cannot be loaded as Python module.
[Thu Nov 03 03:46:24.640328 2016] [wsgi:error] [pid 5953:tid 140142112253696] [client 71.42.119.84:63628] mod_wsgi (pid=5953): Exception occurred processing WSGI script '/var/www/cs373f-idb/app.wsgi'.
[Thu Nov 03 03:46:24.640496 2016] [wsgi:error] [pid 5953:tid 140142112253696] [client 71.42.119.84:63628] Traceback (most recent call last):
[Thu Nov 03 03:46:24.640542 2016] [wsgi:error] [pid 5953:tid 140142112253696] [client 71.42.119.84:63628]   File "/var/www/cs373f-idb/app.wsgi", line 7, in <module>
[Thu Nov 03 03:46:24.640553 2016] [wsgi:error] [pid 5953:tid 140142112253696] [client 71.42.119.84:63628]     from app.app import app as application
[Thu Nov 03 03:46:24.640568 2016] [wsgi:error] [pid 5953:tid 140142112253696] [client 71.42.119.84:63628]   File "/var/www/cs373f-idb/app/app.py", line 9, in <module>
[Thu Nov 03 03:46:24.640576 2016] [wsgi:error] [pid 5953:tid 140142112253696] [client 71.42.119.84:63628]     import models
[Thu Nov 03 03:46:24.640607 2016] [wsgi:error] [pid 5953:tid 140142112253696] [client 71.42.119.84:63628] ImportError: No module named 'models'
[Thu Nov 03 03:46:34.661948 2016] [wsgi:error] [pid 5953:tid 140141955868416] [client 71.42.119.84:63826] mod_wsgi (pid=5953): Target WSGI script '/var/www/cs373f-idb/app.wsgi' cannot be loaded as Python module.
[Thu Nov 03 03:46:34.662115 2016] [wsgi:error] [pid 5953:tid 140141955868416] [client 71.42.119.84:63826] mod_wsgi (pid=5953): Exception occurred processing WSGI script '/var/www/cs373f-idb/app.wsgi'.
[Thu Nov 03 03:46:34.662356 2016] [wsgi:error] [pid 5953:tid 140141955868416] [client 71.42.119.84:63826] Traceback (most recent call last):
[Thu Nov 03 03:46:34.662430 2016] [wsgi:error] [pid 5953:tid 140141955868416] [client 71.42.119.84:63826]   File "/var/www/cs373f-idb/app.wsgi", line 7, in <module>
[Thu Nov 03 03:46:34.662448 2016] [wsgi:error] [pid 5953:tid 140141955868416] [client 71.42.119.84:63826]     from app.app import app as application
[Thu Nov 03 03:46:34.662538 2016] [wsgi:error] [pid 5953:tid 140141955868416] [client 71.42.119.84:63826]   File "/var/www/cs373f-idb/app/app.py", line 9, in <module>
[Thu Nov 03 03:46:34.662556 2016] [wsgi:error] [pid 5953:tid 140141955868416] [client 71.42.119.84:63826]     import models
[Thu Nov 03 03:46:34.662606 2016] [wsgi:error] [pid 5953:tid 140141955868416] [client 71.42.119.84:63826] ImportError: No module named 'models'
[Thu Nov 03 03:47:22.238849 2016] [wsgi:error] [pid 5953:tid 140141871941376] [client 71.42.119.84:63996] mod_wsgi (pid=5953): Target WSGI script '/var/www/cs373f-idb/app.wsgi' cannot be loaded as Python module.
[Thu Nov 03 03:47:22.238964 2016] [wsgi:error] [pid 5953:tid 140141871941376] [client 71.42.119.84:63996] mod_wsgi (pid=5953): Exception occurred processing WSGI script '/var/www/cs373f-idb/app.wsgi'.
[Thu Nov 03 03:47:22.239126 2016] [wsgi:error] [pid 5953:tid 140141871941376] [client 71.42.119.84:63996] Traceback (most recent call last):
[Thu Nov 03 03:47:22.239173 2016] [wsgi:error] [pid 5953:tid 140141871941376] [client 71.42.119.84:63996]   File "/var/www/cs373f-idb/app.wsgi", line 7, in <module>
[Thu Nov 03 03:47:22.239184 2016] [wsgi:error] [pid 5953:tid 140141871941376] [client 71.42.119.84:63996]     from app.app import app as application
[Thu Nov 03 03:47:22.239199 2016] [wsgi:error] [pid 5953:tid 140141871941376] [client 71.42.119.84:63996]   File "/var/www/cs373f-idb/app/app.py", line 9, in <module>
[Thu Nov 03 03:47:22.239207 2016] [wsgi:error] [pid 5953:tid 140141871941376] [client 71.42.119.84:63996]     import models
[Thu Nov 03 03:47:22.239239 2016] [wsgi:error] [pid 5953:tid 140141871941376] [client 71.42.119.84:63996] ImportError: No module named 'models'
[Thu Nov 03 03:47:24.567126 2016] [wsgi:error] [pid 5953:tid 140141863548672] [client 71.42.119.84:63995] mod_wsgi (pid=5953): Target WSGI script '/var/www/cs373f-idb/app.wsgi' cannot be loaded as Python module.
[Thu Nov 03 03:47:24.567281 2016] [wsgi:error] [pid 5953:tid 140141863548672] [client 71.42.119.84:63995] mod_wsgi (pid=5953): Exception occurred processing WSGI script '/var/www/cs373f-idb/app.wsgi'.
[Thu Nov 03 03:47:24.567525 2016] [wsgi:error] [pid 5953:tid 140141863548672] [client 71.42.119.84:63995] Traceback (most recent call last):
[Thu Nov 03 03:47:24.567599 2016] [wsgi:error] [pid 5953:tid 140141863548672] [client 71.42.119.84:63995]   File "/var/www/cs373f-idb/app.wsgi", line 7, in <module>
[Thu Nov 03 03:47:24.567617 2016] [wsgi:error] [pid 5953:tid 140141863548672] [client 71.42.119.84:63995]     from app.app import app as application
[Thu Nov 03 03:47:24.567715 2016] [wsgi:error] [pid 5953:tid 140141863548672] [client 71.42.119.84:63995]   File "/var/www/cs373f-idb/app/app.py", line 9, in <module>
[Thu Nov 03 03:47:24.567728 2016] [wsgi:error] [pid 5953:tid 140141863548672] [client 71.42.119.84:63995]     import models
[Thu Nov 03 03:47:24.567762 2016] [wsgi:error] [pid 5953:tid 140141863548672] [client 71.42.119.84:63995] ImportError: No module named 'models'
[Thu Nov 03 06:27:38.026325 2016] [wsgi:error] [pid 9128:tid 139679145510656] [client 71.42.119.84:63412] mod_wsgi (pid=9128): Target WSGI script '/var/www/cs373f-idb/app.wsgi' cannot be loaded as Python module., referer: http://vgidb.me/
[Thu Nov 03 06:27:38.026481 2016] [wsgi:error] [pid 9128:tid 139679145510656] [client 71.42.119.84:63412] mod_wsgi (pid=9128): Exception occurred processing WSGI script '/var/www/cs373f-idb/app.wsgi'., referer: http://vgidb.me/
[Thu Nov 03 06:27:38.027379 2016] [wsgi:error] [pid 9128:tid 139679145510656] [client 71.42.119.84:63412] Traceback (most recent call last):, referer: http://vgidb.me/
[Thu Nov 03 06:27:38.027449 2016] [wsgi:error] [pid 9128:tid 139679145510656] [client 71.42.119.84:63412]   File "/var/www/cs373f-idb/app.wsgi", line 7, in <module>, referer: http://vgidb.me/
[Thu Nov 03 06:27:38.027465 2016] [wsgi:error] [pid 9128:tid 139679145510656] [client 71.42.119.84:63412]     from app.app import app as application, referer: http://vgidb.me/
[Thu Nov 03 06:27:38.027498 2016] [wsgi:error] [pid 9128:tid 139679145510656] [client 71.42.119.84:63412]   File "/var/www/cs373f-idb/app/app.py", line 8, in <module>, referer: http://vgidb.me/
[Thu Nov 03 06:27:38.027507 2016] [wsgi:error] [pid 9128:tid 139679145510656] [client 71.42.119.84:63412]     from tests import runTestsOut, referer: http://vgidb.me/
[Thu Nov 03 06:27:38.027557 2016] [wsgi:error] [pid 9128:tid 139679145510656] [client 71.42.119.84:63412] ImportError: No module named 'tests', referer: http://vgidb.me/
[Thu Nov 03 06:27:38.684589 2016] [wsgi:error] [pid 9129:tid 139679162296064] [client 71.42.119.84:63421] mod_wsgi (pid=9129): Target WSGI script '/var/www/cs373f-idb/app.wsgi' cannot be loaded as Python module., referer: http://vgidb.me/
[Thu Nov 03 06:27:38.684736 2016] [wsgi:error] [pid 9129:tid 139679162296064] [client 71.42.119.84:63421] mod_wsgi (pid=9129): Exception occurred processing WSGI script '/var/www/cs373f-idb/app.wsgi'., referer: http://vgidb.me/
[Thu Nov 03 06:27:38.685619 2016] [wsgi:error] [pid 9129:tid 139679162296064] [client 71.42.119.84:63421] Traceback (most recent call last):, referer: http://vgidb.me/
[Thu Nov 03 06:27:38.685676 2016] [wsgi:error] [pid 9129:tid 139679162296064] [client 71.42.119.84:63421]   File "/var/www/cs373f-idb/app.wsgi", line 7, in <module>, referer: http://vgidb.me/
[Thu Nov 03 06:27:38.685688 2016] [wsgi:error] [pid 9129:tid 139679162296064] [client 71.42.119.84:63421]     from app.app import app as application, referer: http://vgidb.me/
[Thu Nov 03 06:27:38.685704 2016] [wsgi:error] [pid 9129:tid 139679162296064] [client 71.42.119.84:63421]   File "/var/www/cs373f-idb/app/app.py", line 8, in <module>, referer: http://vgidb.me/
[Thu Nov 03 06:27:38.685713 2016] [wsgi:error] [pid 9129:tid 139679162296064] [client 71.42.119.84:63421]     from tests import runTestsOut, referer: http://vgidb.me/
[Thu Nov 03 06:27:38.685753 2016] [wsgi:error] [pid 9129:tid 139679162296064] [client 71.42.119.84:63421] ImportError: No module named 'tests', referer: http://vgidb.me/
[Thu Nov 03 06:27:47.648806 2016] [wsgi:error] [pid 9129:tid 139679137109760] [client 71.42.119.84:63704] mod_wsgi (pid=9129): Target WSGI script '/var/www/cs373f-idb/app.wsgi' cannot be loaded as Python module.
[Thu Nov 03 06:27:47.648983 2016] [wsgi:error] [pid 9129:tid 139679137109760] [client 71.42.119.84:63704] mod_wsgi (pid=9129): Exception occurred processing WSGI script '/var/www/cs373f-idb/app.wsgi'.
[Thu Nov 03 06:27:47.649247 2016] [wsgi:error] [pid 9129:tid 139679137109760] [client 71.42.119.84:63704] Traceback (most recent call last):
[Thu Nov 03 06:27:47.649326 2016] [wsgi:error] [pid 9129:tid 139679137109760] [client 71.42.119.84:63704]   File "/var/www/cs373f-idb/app.wsgi", line 7, in <module>
[Thu Nov 03 06:27:47.649344 2016] [wsgi:error] [pid 9129:tid 139679137109760] [client 71.42.119.84:63704]     from app.app import app as application
[Thu Nov 03 06:27:47.649368 2016] [wsgi:error] [pid 9129:tid 139679137109760] [client 71.42.119.84:63704]   File "/var/www/cs373f-idb/app/app.py", line 8, in <module>
[Thu Nov 03 06:27:47.649381 2016] [wsgi:error] [pid 9129:tid 139679137109760] [client 71.42.119.84:63704]     from tests import runTestsOut
[Thu Nov 03 06:27:47.649432 2016] [wsgi:error] [pid 9129:tid 139679137109760] [client 71.42.119.84:63704] ImportError: No module named 'tests'
[Thu Nov 03 06:29:48.844312 2016] [wsgi:error] [pid 9261:tid 139800774371072] [client 71.42.119.84:62767] mod_wsgi (pid=9261): Target WSGI script '/var/www/cs373f-idb/app.wsgi' cannot be loaded as Python module.
[Thu Nov 03 06:29:48.844477 2016] [wsgi:error] [pid 9261:tid 139800774371072] [client 71.42.119.84:62767] mod_wsgi (pid=9261): Exception occurred processing WSGI script '/var/www/cs373f-idb/app.wsgi'.
[Thu Nov 03 06:29:48.845165 2016] [wsgi:error] [pid 9261:tid 139800774371072] [client 71.42.119.84:62767] Traceback (most recent call last):
[Thu Nov 03 06:29:48.845218 2016] [wsgi:error] [pid 9261:tid 139800774371072] [client 71.42.119.84:62767]   File "/var/www/cs373f-idb/app.wsgi", line 7, in <module>
[Thu Nov 03 06:29:48.845255 2016] [wsgi:error] [pid 9261:tid 139800774371072] [client 71.42.119.84:62767]     from app.app import app as application
[Thu Nov 03 06:29:48.845277 2016] [wsgi:error] [pid 9261:tid 139800774371072] [client 71.42.119.84:62767]   File "/var/www/cs373f-idb/app/app.py", line 8, in <module>
[Thu Nov 03 06:29:48.845286 2016] [wsgi:error] [pid 9261:tid 139800774371072] [client 71.42.119.84:62767]     from tests import runTestsOut
[Thu Nov 03 06:29:48.845324 2016] [wsgi:error] [pid 9261:tid 139800774371072] [client 71.42.119.84:62767] ImportError: No module named 'tests'
[Thu Nov 03 06:31:30.266961 2016] [wsgi:error] [pid 9383:tid 140013241100032] [client 71.42.119.84:63687] mod_wsgi (pid=9383): Target WSGI script '/var/www/cs373f-idb/app.wsgi' cannot be loaded as Python module.
[Thu Nov 03 06:31:30.267132 2016] [wsgi:error] [pid 9383:tid 140013241100032] [client 71.42.119.84:63687] mod_wsgi (pid=9383): Exception occurred processing WSGI script '/var/www/cs373f-idb/app.wsgi'.
[Thu Nov 03 06:31:30.268157 2016] [wsgi:error] [pid 9383:tid 140013241100032] [client 71.42.119.84:63687] Traceback (most recent call last):
[Thu Nov 03 06:31:30.268222 2016] [wsgi:error] [pid 9383:tid 140013241100032] [client 71.42.119.84:63687]   File "/var/www/cs373f-idb/app.wsgi", line 7, in <module>
[Thu Nov 03 06:31:30.268235 2016] [wsgi:error] [pid 9383:tid 140013241100032] [client 71.42.119.84:63687]     from app.app import app as application
[Thu Nov 03 06:31:30.268250 2016] [wsgi:error] [pid 9383:tid 140013241100032] [client 71.42.119.84:63687]   File "/var/www/cs373f-idb/app/app.py", line 8, in <module>
[Thu Nov 03 06:31:30.268258 2016] [wsgi:error] [pid 9383:tid 140013241100032] [client 71.42.119.84:63687]     from app.tests import runTestsOut
[Thu Nov 03 06:31:30.268272 2016] [wsgi:error] [pid 9383:tid 140013241100032] [client 71.42.119.84:63687]   File "/var/www/cs373f-idb/app/tests.py", line 4, in <module>
[Thu Nov 03 06:31:30.268279 2016] [wsgi:error] [pid 9383:tid 140013241100032] [client 71.42.119.84:63687]     from models \t\timport *
[Thu Nov 03 06:31:30.268314 2016] [wsgi:error] [pid 9383:tid 140013241100032] [client 71.42.119.84:63687] ImportError: No module named 'models'
[Thu Nov 03 06:31:40.148701 2016] [wsgi:error] [pid 9384:tid 140013173958400] [client 71.42.119.84:64008] mod_wsgi (pid=9384): Target WSGI script '/var/www/cs373f-idb/app.wsgi' cannot be loaded as Python module.
[Thu Nov 03 06:31:40.148923 2016] [wsgi:error] [pid 9384:tid 140013173958400] [client 71.42.119.84:64008] mod_wsgi (pid=9384): Exception occurred processing WSGI script '/var/www/cs373f-idb/app.wsgi'.
[Thu Nov 03 06:31:40.149949 2016] [wsgi:error] [pid 9384:tid 140013173958400] [client 71.42.119.84:64008] Traceback (most recent call last):
[Thu Nov 03 06:31:40.150046 2016] [wsgi:error] [pid 9384:tid 140013173958400] [client 71.42.119.84:64008]   File "/var/www/cs373f-idb/app.wsgi", line 7, in <module>
[Thu Nov 03 06:31:40.150069 2016] [wsgi:error] [pid 9384:tid 140013173958400] [client 71.42.119.84:64008]     from app.app import app as application
[Thu Nov 03 06:31:40.150103 2016] [wsgi:error] [pid 9384:tid 140013173958400] [client 71.42.119.84:64008]   File "/var/www/cs373f-idb/app/app.py", line 8, in <module>
[Thu Nov 03 06:31:40.150115 2016] [wsgi:error] [pid 9384:tid 140013173958400] [client 71.42.119.84:64008]     from app.tests import runTestsOut
[Thu Nov 03 06:31:40.150130 2016] [wsgi:error] [pid 9384:tid 140013173958400] [client 71.42.119.84:64008]   File "/var/www/cs373f-idb/app/tests.py", line 4, in <module>
[Thu Nov 03 06:31:40.150138 2016] [wsgi:error] [pid 9384:tid 140013173958400] [client 71.42.119.84:64008]     from models \t\timport *
[Thu Nov 03 06:31:40.150178 2016] [wsgi:error] [pid 9384:tid 140013173958400] [client 71.42.119.84:64008] ImportError: No module named 'models'
[Thu Nov 03 06:39:36.382640 2016] [wsgi:error] [pid 10085:tid 140490502555392] [client 71.42.119.84:62828] [2016-11-03 06:39:36,379] ERROR in app: Exception on /api/platforms/44 [GET]
[Thu Nov 03 06:39:36.382975 2016] [wsgi:error] [pid 10085:tid 140490502555392] [client 71.42.119.84:62828] Traceback (most recent call last):
[Thu Nov 03 06:39:36.382987 2016] [wsgi:error] [pid 10085:tid 140490502555392] [client 71.42.119.84:62828]   File "/usr/local/lib/python3.5/dist-packages/flask/app.py", line 1988, in wsgi_app
[Thu Nov 03 06:39:36.382993 2016] [wsgi:error] [pid 10085:tid 140490502555392] [client 71.42.119.84:62828]     response = self.full_dispatch_request()
[Thu Nov 03 06:39:36.382999 2016] [wsgi:error] [pid 10085:tid 140490502555392] [client 71.42.119.84:62828]   File "/usr/local/lib/python3.5/dist-packages/flask/app.py", line 1641, in full_dispatch_request
[Thu Nov 03 06:39:36.383004 2016] [wsgi:error] [pid 10085:tid 140490502555392] [client 71.42.119.84:62828]     rv = self.handle_user_exception(e)
[Thu Nov 03 06:39:36.383009 2016] [wsgi:error] [pid 10085:tid 140490502555392] [client 71.42.119.84:62828]   File "/usr/local/lib/python3.5/dist-packages/flask/app.py", line 1544, in handle_user_exception
[Thu Nov 03 06:39:36.383014 2016] [wsgi:error] [pid 10085:tid 140490502555392] [client 71.42.119.84:62828]     reraise(exc_type, exc_value, tb)
[Thu Nov 03 06:39:36.383019 2016] [wsgi:error] [pid 10085:tid 140490502555392] [client 71.42.119.84:62828]   File "/usr/local/lib/python3.5/dist-packages/flask/_compat.py", line 33, in reraise
[Thu Nov 03 06:39:36.383024 2016] [wsgi:error] [pid 10085:tid 140490502555392] [client 71.42.119.84:62828]     raise value
[Thu Nov 03 06:39:36.383029 2016] [wsgi:error] [pid 10085:tid 140490502555392] [client 71.42.119.84:62828]   File "/usr/local/lib/python3.5/dist-packages/flask/app.py", line 1639, in full_dispatch_request
[Thu Nov 03 06:39:36.383034 2016] [wsgi:error] [pid 10085:tid 140490502555392] [client 71.42.119.84:62828]     rv = self.dispatch_request()
[Thu Nov 03 06:39:36.383039 2016] [wsgi:error] [pid 10085:tid 140490502555392] [client 71.42.119.84:62828]   File "/usr/local/lib/python3.5/dist-packages/flask/app.py", line 1625, in dispatch_request
[Thu Nov 03 06:39:36.383044 2016] [wsgi:error] [pid 10085:tid 140490502555392] [client 71.42.119.84:62828]     return self.view_functions[rule.endpoint](**req.view_args)
[Thu Nov 03 06:39:36.383049 2016] [wsgi:error] [pid 10085:tid 140490502555392] [client 71.42.119.84:62828]   File "/var/www/cs373f-idb/app/app.py", line 250, in api_platforms_id
[Thu Nov 03 06:39:36.383054 2016] [wsgi:error] [pid 10085:tid 140490502555392] [client 71.42.119.84:62828]     return jsonify(Platform.query.get(id).serialize())
[Thu Nov 03 06:39:36.383064 2016] [wsgi:error] [pid 10085:tid 140490502555392] [client 71.42.119.84:62828] AttributeError: 'NoneType' object has no attribute 'serialize'
[Thu Nov 03 06:39:36.383103 2016] [wsgi:error] [pid 10085:tid 140490502555392] [client 71.42.119.84:62828] 
[Thu Nov 03 06:39:40.906543 2016] [wsgi:error] [pid 10054:tid 140490485769984] [client 71.42.119.84:62831] [2016-11-03 06:39:40,903] ERROR in app: Exception on /api/platforms/44 [GET]
[Thu Nov 03 06:39:40.906621 2016] [wsgi:error] [pid 10054:tid 140490485769984] [client 71.42.119.84:62831] Traceback (most recent call last):
[Thu Nov 03 06:39:40.906628 2016] [wsgi:error] [pid 10054:tid 140490485769984] [client 71.42.119.84:62831]   File "/usr/local/lib/python3.5/dist-packages/flask/app.py", line 1988, in wsgi_app
[Thu Nov 03 06:39:40.906634 2016] [wsgi:error] [pid 10054:tid 140490485769984] [client 71.42.119.84:62831]     response = self.full_dispatch_request()
[Thu Nov 03 06:39:40.906640 2016] [wsgi:error] [pid 10054:tid 140490485769984] [client 71.42.119.84:62831]   File "/usr/local/lib/python3.5/dist-packages/flask/app.py", line 1641, in full_dispatch_request
[Thu Nov 03 06:39:40.906645 2016] [wsgi:error] [pid 10054:tid 140490485769984] [client 71.42.119.84:62831]     rv = self.handle_user_exception(e)
[Thu Nov 03 06:39:40.906651 2016] [wsgi:error] [pid 10054:tid 140490485769984] [client 71.42.119.84:62831]   File "/usr/local/lib/python3.5/dist-packages/flask/app.py", line 1544, in handle_user_exception
[Thu Nov 03 06:39:40.906656 2016] [wsgi:error] [pid 10054:tid 140490485769984] [client 71.42.119.84:62831]     reraise(exc_type, exc_value, tb)
[Thu Nov 03 06:39:40.906698 2016] [wsgi:error] [pid 10054:tid 140490485769984] [client 71.42.119.84:62831]   File "/usr/local/lib/python3.5/dist-packages/flask/_compat.py", line 33, in reraise
[Thu Nov 03 06:39:40.906705 2016] [wsgi:error] [pid 10054:tid 140490485769984] [client 71.42.119.84:62831]     raise value
[Thu Nov 03 06:39:40.906711 2016] [wsgi:error] [pid 10054:tid 140490485769984] [client 71.42.119.84:62831]   File "/usr/local/lib/python3.5/dist-packages/flask/app.py", line 1639, in full_dispatch_request
[Thu Nov 03 06:39:40.906716 2016] [wsgi:error] [pid 10054:tid 140490485769984] [client 71.42.119.84:62831]     rv = self.dispatch_request()
[Thu Nov 03 06:39:40.906721 2016] [wsgi:error] [pid 10054:tid 140490485769984] [client 71.42.119.84:62831]   File "/usr/local/lib/python3.5/dist-packages/flask/app.py", line 1625, in dispatch_request
[Thu Nov 03 06:39:40.906726 2016] [wsgi:error] [pid 10054:tid 140490485769984] [client 71.42.119.84:62831]     return self.view_functions[rule.endpoint](**req.view_args)
[Thu Nov 03 06:39:40.906731 2016] [wsgi:error] [pid 10054:tid 140490485769984] [client 71.42.119.84:62831]   File "/var/www/cs373f-idb/app/app.py", line 250, in api_platforms_id
[Thu Nov 03 06:39:40.906736 2016] [wsgi:error] [pid 10054:tid 140490485769984] [client 71.42.119.84:62831]     return jsonify(Platform.query.get(id).serialize())
[Thu Nov 03 06:39:40.906744 2016] [wsgi:error] [pid 10054:tid 140490485769984] [client 71.42.119.84:62831] AttributeError: 'NoneType' object has no attribute 'serialize'
[Thu Nov 03 06:39:40.906788 2016] [wsgi:error] [pid 10054:tid 140490485769984] [client 71.42.119.84:62831] 
[Thu Nov 03 06:39:42.271507 2016] [wsgi:error] [pid 10054:tid 140490477377280] [client 71.42.119.84:62829] [2016-11-03 06:39:42,270] ERROR in app: Exception on /api/platforms/44 [GET]
[Thu Nov 03 06:39:42.271569 2016] [wsgi:error] [pid 10054:tid 140490477377280] [client 71.42.119.84:62829] Traceback (most recent call last):
[Thu Nov 03 06:39:42.271576 2016] [wsgi:error] [pid 10054:tid 140490477377280] [client 71.42.119.84:62829]   File "/usr/local/lib/python3.5/dist-packages/flask/app.py", line 1988, in wsgi_app
[Thu Nov 03 06:39:42.271582 2016] [wsgi:error] [pid 10054:tid 140490477377280] [client 71.42.119.84:62829]     response = self.full_dispatch_request()
[Thu Nov 03 06:39:42.271587 2016] [wsgi:error] [pid 10054:tid 140490477377280] [client 71.42.119.84:62829]   File "/usr/local/lib/python3.5/dist-packages/flask/app.py", line 1641, in full_dispatch_request
[Thu Nov 03 06:39:42.271592 2016] [wsgi:error] [pid 10054:tid 140490477377280] [client 71.42.119.84:62829]     rv = self.handle_user_exception(e)
[Thu Nov 03 06:39:42.271597 2016] [wsgi:error] [pid 10054:tid 140490477377280] [client 71.42.119.84:62829]   File "/usr/local/lib/python3.5/dist-packages/flask/app.py", line 1544, in handle_user_exception
[Thu Nov 03 06:39:42.271602 2016] [wsgi:error] [pid 10054:tid 140490477377280] [client 71.42.119.84:62829]     reraise(exc_type, exc_value, tb)
[Thu Nov 03 06:39:42.271608 2016] [wsgi:error] [pid 10054:tid 140490477377280] [client 71.42.119.84:62829]   File "/usr/local/lib/python3.5/dist-packages/flask/_compat.py", line 33, in reraise
[Thu Nov 03 06:39:42.271613 2016] [wsgi:error] [pid 10054:tid 140490477377280] [client 71.42.119.84:62829]     raise value
[Thu Nov 03 06:39:42.271618 2016] [wsgi:error] [pid 10054:tid 140490477377280] [client 71.42.119.84:62829]   File "/usr/local/lib/python3.5/dist-packages/flask/app.py", line 1639, in full_dispatch_request
[Thu Nov 03 06:39:42.271623 2016] [wsgi:error] [pid 10054:tid 140490477377280] [client 71.42.119.84:62829]     rv = self.dispatch_request()
[Thu Nov 03 06:39:42.271628 2016] [wsgi:error] [pid 10054:tid 140490477377280] [client 71.42.119.84:62829]   File "/usr/local/lib/python3.5/dist-packages/flask/app.py", line 1625, in dispatch_request
[Thu Nov 03 06:39:42.271633 2016] [wsgi:error] [pid 10054:tid 140490477377280] [client 71.42.119.84:62829]     return self.view_functions[rule.endpoint](**req.view_args)
[Thu Nov 03 06:39:42.271684 2016] [wsgi:error] [pid 10054:tid 140490477377280] [client 71.42.119.84:62829]   File "/var/www/cs373f-idb/app/app.py", line 250, in api_platforms_id
[Thu Nov 03 06:39:42.271693 2016] [wsgi:error] [pid 10054:tid 140490477377280] [client 71.42.119.84:62829]     return jsonify(Platform.query.get(id).serialize())
[Thu Nov 03 06:39:42.271701 2016] [wsgi:error] [pid 10054:tid 140490477377280] [client 71.42.119.84:62829] AttributeError: 'NoneType' object has no attribute 'serialize'
[Thu Nov 03 06:39:42.271736 2016] [wsgi:error] [pid 10054:tid 140490477377280] [client 71.42.119.84:62829] 
[Thu Nov 03 06:39:43.467139 2016] [wsgi:error] [pid 10085:tid 140490494162688] [client 71.42.119.84:62830] [2016-11-03 06:39:43,466] ERROR in app: Exception on /api/platforms/44 [GET]
[Thu Nov 03 06:39:43.467190 2016] [wsgi:error] [pid 10085:tid 140490494162688] [client 71.42.119.84:62830] Traceback (most recent call last):
[Thu Nov 03 06:39:43.467197 2016] [wsgi:error] [pid 10085:tid 140490494162688] [client 71.42.119.84:62830]   File "/usr/local/lib/python3.5/dist-packages/flask/app.py", line 1988, in wsgi_app
[Thu Nov 03 06:39:43.467203 2016] [wsgi:error] [pid 10085:tid 140490494162688] [client 71.42.119.84:62830]     response = self.full_dispatch_request()
[Thu Nov 03 06:39:43.467208 2016] [wsgi:error] [pid 10085:tid 140490494162688] [client 71.42.119.84:62830]   File "/usr/local/lib/python3.5/dist-packages/flask/app.py", line 1641, in full_dispatch_request
[Thu Nov 03 06:39:43.467213 2016] [wsgi:error] [pid 10085:tid 140490494162688] [client 71.42.119.84:62830]     rv = self.handle_user_exception(e)
[Thu Nov 03 06:39:43.467218 2016] [wsgi:error] [pid 10085:tid 140490494162688] [client 71.42.119.84:62830]   File "/usr/local/lib/python3.5/dist-packages/flask/app.py", line 1544, in handle_user_exception
[Thu Nov 03 06:39:43.467223 2016] [wsgi:error] [pid 10085:tid 140490494162688] [client 71.42.119.84:62830]     reraise(exc_type, exc_value, tb)
[Thu Nov 03 06:39:43.467228 2016] [wsgi:error] [pid 10085:tid 140490494162688] [client 71.42.119.84:62830]   File "/usr/local/lib/python3.5/dist-packages/flask/_compat.py", line 33, in reraise
[Thu Nov 03 06:39:43.467233 2016] [wsgi:error] [pid 10085:tid 140490494162688] [client 71.42.119.84:62830]     raise value
[Thu Nov 03 06:39:43.467238 2016] [wsgi:error] [pid 10085:tid 140490494162688] [client 71.42.119.84:62830]   File "/usr/local/lib/python3.5/dist-packages/flask/app.py", line 1639, in full_dispatch_request
[Thu Nov 03 06:39:43.467243 2016] [wsgi:error] [pid 10085:tid 140490494162688] [client 71.42.119.84:62830]     rv = self.dispatch_request()
[Thu Nov 03 06:39:43.467248 2016] [wsgi:error] [pid 10085:tid 140490494162688] [client 71.42.119.84:62830]   File "/usr/local/lib/python3.5/dist-packages/flask/app.py", line 1625, in dispatch_request
[Thu Nov 03 06:39:43.467253 2016] [wsgi:error] [pid 10085:tid 140490494162688] [client 71.42.119.84:62830]     return self.view_functions[rule.endpoint](**req.view_args)
[Thu Nov 03 06:39:43.467258 2016] [wsgi:error] [pid 10085:tid 140490494162688] [client 71.42.119.84:62830]   File "/var/www/cs373f-idb/app/app.py", line 250, in api_platforms_id
[Thu Nov 03 06:39:43.467263 2016] [wsgi:error] [pid 10085:tid 140490494162688] [client 71.42.119.84:62830]     return jsonify(Platform.query.get(id).serialize())
[Thu Nov 03 06:39:43.467271 2016] [wsgi:error] [pid 10085:tid 140490494162688] [client 71.42.119.84:62830] AttributeError: 'NoneType' object has no attribute 'serialize'
[Thu Nov 03 06:39:43.467299 2016] [wsgi:error] [pid 10085:tid 140490494162688] [client 71.42.119.84:62830] 
[Thu Nov 03 06:39:44.382126 2016] [wsgi:error] [pid 10054:tid 140490468984576] [client 71.42.119.84:62974] [2016-11-03 06:39:44,381] ERROR in app: Exception on /api/platforms/44 [GET]
[Thu Nov 03 06:39:44.382193 2016] [wsgi:error] [pid 10054:tid 140490468984576] [client 71.42.119.84:62974] Traceback (most recent call last):
[Thu Nov 03 06:39:44.382200 2016] [wsgi:error] [pid 10054:tid 140490468984576] [client 71.42.119.84:62974]   File "/usr/local/lib/python3.5/dist-packages/flask/app.py", line 1988, in wsgi_app
[Thu Nov 03 06:39:44.382234 2016] [wsgi:error] [pid 10054:tid 140490468984576] [client 71.42.119.84:62974]     response = self.full_dispatch_request()
[Thu Nov 03 06:39:44.382241 2016] [wsgi:error] [pid 10054:tid 140490468984576] [client 71.42.119.84:62974]   File "/usr/local/lib/python3.5/dist-packages/flask/app.py", line 1641, in full_dispatch_request
[Thu Nov 03 06:39:44.382247 2016] [wsgi:error] [pid 10054:tid 140490468984576] [client 71.42.119.84:62974]     rv = self.handle_user_exception(e)
[Thu Nov 03 06:39:44.382252 2016] [wsgi:error] [pid 10054:tid 140490468984576] [client 71.42.119.84:62974]   File "/usr/local/lib/python3.5/dist-packages/flask/app.py", line 1544, in handle_user_exception
[Thu Nov 03 06:39:44.382257 2016] [wsgi:error] [pid 10054:tid 140490468984576] [client 71.42.119.84:62974]     reraise(exc_type, exc_value, tb)
[Thu Nov 03 06:39:44.382262 2016] [wsgi:error] [pid 10054:tid 140490468984576] [client 71.42.119.84:62974]   File "/usr/local/lib/python3.5/dist-packages/flask/_compat.py", line 33, in reraise
[Thu Nov 03 06:39:44.382268 2016] [wsgi:error] [pid 10054:tid 140490468984576] [client 71.42.119.84:62974]     raise value
[Thu Nov 03 06:39:44.382273 2016] [wsgi:error] [pid 10054:tid 140490468984576] [client 71.42.119.84:62974]   File "/usr/local/lib/python3.5/dist-packages/flask/app.py", line 1639, in full_dispatch_request
[Thu Nov 03 06:39:44.382278 2016] [wsgi:error] [pid 10054:tid 140490468984576] [client 71.42.119.84:62974]     rv = self.dispatch_request()
[Thu Nov 03 06:39:44.382283 2016] [wsgi:error] [pid 10054:tid 140490468984576] [client 71.42.119.84:62974]   File "/usr/local/lib/python3.5/dist-packages/flask/app.py", line 1625, in dispatch_request
[Thu Nov 03 06:39:44.382288 2016] [wsgi:error] [pid 10054:tid 140490468984576] [client 71.42.119.84:62974]     return self.view_functions[rule.endpoint](**req.view_args)
[Thu Nov 03 06:39:44.382293 2016] [wsgi:error] [pid 10054:tid 140490468984576] [client 71.42.119.84:62974]   File "/var/www/cs373f-idb/app/app.py", line 250, in api_platforms_id
[Thu Nov 03 06:39:44.382298 2016] [wsgi:error] [pid 10054:tid 140490468984576] [client 71.42.119.84:62974]     return jsonify(Platform.query.get(id).serialize())
[Thu Nov 03 06:39:44.382306 2016] [wsgi:error] [pid 10054:tid 140490468984576] [client 71.42.119.84:62974] AttributeError: 'NoneType' object has no attribute 'serialize'
[Thu Nov 03 06:39:44.382338 2016] [wsgi:error] [pid 10054:tid 140490468984576] [client 71.42.119.84:62974] 
[Thu Nov 03 06:40:20.731540 2016] [wsgi:error] [pid 10085:tid 140490485769984] [client 71.42.119.84:63763] [2016-11-03 06:40:20,729] ERROR in app: Exception on /api/platforms/44 [GET]
[Thu Nov 03 06:40:20.731641 2016] [wsgi:error] [pid 10085:tid 140490485769984] [client 71.42.119.84:63763] Traceback (most recent call last):
[Thu Nov 03 06:40:20.731649 2016] [wsgi:error] [pid 10085:tid 140490485769984] [client 71.42.119.84:63763]   File "/usr/local/lib/python3.5/dist-packages/flask/app.py", line 1988, in wsgi_app
[Thu Nov 03 06:40:20.731656 2016] [wsgi:error] [pid 10085:tid 140490485769984] [client 71.42.119.84:63763]     response = self.full_dispatch_request()
[Thu Nov 03 06:40:20.731662 2016] [wsgi:error] [pid 10085:tid 140490485769984] [client 71.42.119.84:63763]   File "/usr/local/lib/python3.5/dist-packages/flask/app.py", line 1641, in full_dispatch_request
[Thu Nov 03 06:40:20.731668 2016] [wsgi:error] [pid 10085:tid 140490485769984] [client 71.42.119.84:63763]     rv = self.handle_user_exception(e)
[Thu Nov 03 06:40:20.731673 2016] [wsgi:error] [pid 10085:tid 140490485769984] [client 71.42.119.84:63763]   File "/usr/local/lib/python3.5/dist-packages/flask/app.py", line 1544, in handle_user_exception
[Thu Nov 03 06:40:20.731679 2016] [wsgi:error] [pid 10085:tid 140490485769984] [client 71.42.119.84:63763]     reraise(exc_type, exc_value, tb)
[Thu Nov 03 06:40:20.731684 2016] [wsgi:error] [pid 10085:tid 140490485769984] [client 71.42.119.84:63763]   File "/usr/local/lib/python3.5/dist-packages/flask/_compat.py", line 33, in reraise
[Thu Nov 03 06:40:20.731715 2016] [wsgi:error] [pid 10085:tid 140490485769984] [client 71.42.119.84:63763]     raise value
[Thu Nov 03 06:40:20.731722 2016] [wsgi:error] [pid 10085:tid 140490485769984] [client 71.42.119.84:63763]   File "/usr/local/lib/python3.5/dist-packages/flask/app.py", line 1639, in full_dispatch_request
[Thu Nov 03 06:40:20.731728 2016] [wsgi:error] [pid 10085:tid 140490485769984] [client 71.42.119.84:63763]     rv = self.dispatch_request()
[Thu Nov 03 06:40:20.731732 2016] [wsgi:error] [pid 10085:tid 140490485769984] [client 71.42.119.84:63763]   File "/usr/local/lib/python3.5/dist-packages/flask/app.py", line 1625, in dispatch_request
[Thu Nov 03 06:40:20.731738 2016] [wsgi:error] [pid 10085:tid 140490485769984] [client 71.42.119.84:63763]     return self.view_functions[rule.endpoint](**req.view_args)
[Thu Nov 03 06:40:20.731743 2016] [wsgi:error] [pid 10085:tid 140490485769984] [client 71.42.119.84:63763]   File "/var/www/cs373f-idb/app/app.py", line 250, in api_platforms_id
[Thu Nov 03 06:40:20.731748 2016] [wsgi:error] [pid 10085:tid 140490485769984] [client 71.42.119.84:63763]     return jsonify(Platform.query.get(id).serialize())
[Thu Nov 03 06:40:20.731756 2016] [wsgi:error] [pid 10085:tid 140490485769984] [client 71.42.119.84:63763] AttributeError: 'NoneType' object has no attribute 'serialize'
[Thu Nov 03 06:40:20.731810 2016] [wsgi:error] [pid 10085:tid 140490485769984] [client 71.42.119.84:63763] 
[Thu Nov 03 06:40:22.099199 2016] [wsgi:error] [pid 10054:tid 140490616870656] [client 71.42.119.84:63783] [2016-11-03 06:40:22,097] ERROR in app: Exception on /api/platforms/44 [GET]
[Thu Nov 03 06:40:22.099260 2016] [wsgi:error] [pid 10054:tid 140490616870656] [client 71.42.119.84:63783] Traceback (most recent call last):
[Thu Nov 03 06:40:22.099266 2016] [wsgi:error] [pid 10054:tid 140490616870656] [client 71.42.119.84:63783]   File "/usr/local/lib/python3.5/dist-packages/flask/app.py", line 1988, in wsgi_app
[Thu Nov 03 06:40:22.099272 2016] [wsgi:error] [pid 10054:tid 140490616870656] [client 71.42.119.84:63783]     response = self.full_dispatch_request()
[Thu Nov 03 06:40:22.099277 2016] [wsgi:error] [pid 10054:tid 140490616870656] [client 71.42.119.84:63783]   File "/usr/local/lib/python3.5/dist-packages/flask/app.py", line 1641, in full_dispatch_request
[Thu Nov 03 06:40:22.099283 2016] [wsgi:error] [pid 10054:tid 140490616870656] [client 71.42.119.84:63783]     rv = self.handle_user_exception(e)
[Thu Nov 03 06:40:22.099288 2016] [wsgi:error] [pid 10054:tid 140490616870656] [client 71.42.119.84:63783]   File "/usr/local/lib/python3.5/dist-packages/flask/app.py", line 1544, in handle_user_exception
[Thu Nov 03 06:40:22.099293 2016] [wsgi:error] [pid 10054:tid 140490616870656] [client 71.42.119.84:63783]     reraise(exc_type, exc_value, tb)
[Thu Nov 03 06:40:22.099298 2016] [wsgi:error] [pid 10054:tid 140490616870656] [client 71.42.119.84:63783]   File "/usr/local/lib/python3.5/dist-packages/flask/_compat.py", line 33, in reraise
[Thu Nov 03 06:40:22.099303 2016] [wsgi:error] [pid 10054:tid 140490616870656] [client 71.42.119.84:63783]     raise value
[Thu Nov 03 06:40:22.099308 2016] [wsgi:error] [pid 10054:tid 140490616870656] [client 71.42.119.84:63783]   File "/usr/local/lib/python3.5/dist-packages/flask/app.py", line 1639, in full_dispatch_request
[Thu Nov 03 06:40:22.099313 2016] [wsgi:error] [pid 10054:tid 140490616870656] [client 71.42.119.84:63783]     rv = self.dispatch_request()
[Thu Nov 03 06:40:22.099318 2016] [wsgi:error] [pid 10054:tid 140490616870656] [client 71.42.119.84:63783]   File "/usr/local/lib/python3.5/dist-packages/flask/app.py", line 1625, in dispatch_request
[Thu Nov 03 06:40:22.099323 2016] [wsgi:error] [pid 10054:tid 140490616870656] [client 71.42.119.84:63783]     return self.view_functions[rule.endpoint](**req.view_args)
[Thu Nov 03 06:40:22.099328 2016] [wsgi:error] [pid 10054:tid 140490616870656] [client 71.42.119.84:63783]   File "/var/www/cs373f-idb/app/app.py", line 250, in api_platforms_id
[Thu Nov 03 06:40:22.099358 2016] [wsgi:error] [pid 10054:tid 140490616870656] [client 71.42.119.84:63783]     return jsonify(Platform.query.get(id).serialize())
[Thu Nov 03 06:40:22.099380 2016] [wsgi:error] [pid 10054:tid 140490616870656] [client 71.42.119.84:63783] AttributeError: 'NoneType' object has no attribute 'serialize'
[Thu Nov 03 06:40:22.099445 2016] [wsgi:error] [pid 10054:tid 140490616870656] [client 71.42.119.84:63783] 
[Thu Nov 03 06:40:24.984349 2016] [wsgi:error] [pid 10054:tid 140490460591872] [client 71.42.119.84:63819] [2016-11-03 06:40:24,983] ERROR in app: Exception on /api/platforms/44 [GET]
[Thu Nov 03 06:40:24.984404 2016] [wsgi:error] [pid 10054:tid 140490460591872] [client 71.42.119.84:63819] Traceback (most recent call last):
[Thu Nov 03 06:40:24.984411 2016] [wsgi:error] [pid 10054:tid 140490460591872] [client 71.42.119.84:63819]   File "/usr/local/lib/python3.5/dist-packages/flask/app.py", line 1988, in wsgi_app
[Thu Nov 03 06:40:24.984417 2016] [wsgi:error] [pid 10054:tid 140490460591872] [client 71.42.119.84:63819]     response = self.full_dispatch_request()
[Thu Nov 03 06:40:24.984422 2016] [wsgi:error] [pid 10054:tid 140490460591872] [client 71.42.119.84:63819]   File "/usr/local/lib/python3.5/dist-packages/flask/app.py", line 1641, in full_dispatch_request
[Thu Nov 03 06:40:24.984428 2016] [wsgi:error] [pid 10054:tid 140490460591872] [client 71.42.119.84:63819]     rv = self.handle_user_exception(e)
[Thu Nov 03 06:40:24.984433 2016] [wsgi:error] [pid 10054:tid 140490460591872] [client 71.42.119.84:63819]   File "/usr/local/lib/python3.5/dist-packages/flask/app.py", line 1544, in handle_user_exception
[Thu Nov 03 06:40:24.984438 2016] [wsgi:error] [pid 10054:tid 140490460591872] [client 71.42.119.84:63819]     reraise(exc_type, exc_value, tb)
[Thu Nov 03 06:40:24.984443 2016] [wsgi:error] [pid 10054:tid 140490460591872] [client 71.42.119.84:63819]   File "/usr/local/lib/python3.5/dist-packages/flask/_compat.py", line 33, in reraise
[Thu Nov 03 06:40:24.984448 2016] [wsgi:error] [pid 10054:tid 140490460591872] [client 71.42.119.84:63819]     raise value
[Thu Nov 03 06:40:24.984453 2016] [wsgi:error] [pid 10054:tid 140490460591872] [client 71.42.119.84:63819]   File "/usr/local/lib/python3.5/dist-packages/flask/app.py", line 1639, in full_dispatch_request
[Thu Nov 03 06:40:24.984458 2016] [wsgi:error] [pid 10054:tid 140490460591872] [client 71.42.119.84:63819]     rv = self.dispatch_request()
[Thu Nov 03 06:40:24.984463 2016] [wsgi:error] [pid 10054:tid 140490460591872] [client 71.42.119.84:63819]   File "/usr/local/lib/python3.5/dist-packages/flask/app.py", line 1625, in dispatch_request
[Thu Nov 03 06:40:24.984468 2016] [wsgi:error] [pid 10054:tid 140490460591872] [client 71.42.119.84:63819]     return self.view_functions[rule.endpoint](**req.view_args)
[Thu Nov 03 06:40:24.984473 2016] [wsgi:error] [pid 10054:tid 140490460591872] [client 71.42.119.84:63819]   File "/var/www/cs373f-idb/app/app.py", line 250, in api_platforms_id
[Thu Nov 03 06:40:24.984478 2016] [wsgi:error] [pid 10054:tid 140490460591872] [client 71.42.119.84:63819]     return jsonify(Platform.query.get(id).serialize())
[Thu Nov 03 06:40:24.984486 2016] [wsgi:error] [pid 10054:tid 140490460591872] [client 71.42.119.84:63819] AttributeError: 'NoneType' object has no attribute 'serialize'
[Thu Nov 03 06:40:24.984514 2016] [wsgi:error] [pid 10054:tid 140490460591872] [client 71.42.119.84:63819] 
[Thu Nov 03 06:40:27.904000 2016] [wsgi:error] [pid 10085:tid 140490608477952] [client 71.42.119.84:63924] [2016-11-03 06:40:27,903] ERROR in app: Exception on /api/platforms/44 [GET]
[Thu Nov 03 06:40:27.904052 2016] [wsgi:error] [pid 10085:tid 140490608477952] [client 71.42.119.84:63924] Traceback (most recent call last):
[Thu Nov 03 06:40:27.904059 2016] [wsgi:error] [pid 10085:tid 140490608477952] [client 71.42.119.84:63924]   File "/usr/local/lib/python3.5/dist-packages/flask/app.py", line 1988, in wsgi_app
[Thu Nov 03 06:40:27.904064 2016] [wsgi:error] [pid 10085:tid 140490608477952] [client 71.42.119.84:63924]     response = self.full_dispatch_request()
[Thu Nov 03 06:40:27.904096 2016] [wsgi:error] [pid 10085:tid 140490608477952] [client 71.42.119.84:63924]   File "/usr/local/lib/python3.5/dist-packages/flask/app.py", line 1641, in full_dispatch_request
[Thu Nov 03 06:40:27.904104 2016] [wsgi:error] [pid 10085:tid 140490608477952] [client 71.42.119.84:63924]     rv = self.handle_user_exception(e)
[Thu Nov 03 06:40:27.904109 2016] [wsgi:error] [pid 10085:tid 140490608477952] [client 71.42.119.84:63924]   File "/usr/local/lib/python3.5/dist-packages/flask/app.py", line 1544, in handle_user_exception
[Thu Nov 03 06:40:27.904115 2016] [wsgi:error] [pid 10085:tid 140490608477952] [client 71.42.119.84:63924]     reraise(exc_type, exc_value, tb)
[Thu Nov 03 06:40:27.904120 2016] [wsgi:error] [pid 10085:tid 140490608477952] [client 71.42.119.84:63924]   File "/usr/local/lib/python3.5/dist-packages/flask/_compat.py", line 33, in reraise
[Thu Nov 03 06:40:27.904125 2016] [wsgi:error] [pid 10085:tid 140490608477952] [client 71.42.119.84:63924]     raise value
[Thu Nov 03 06:40:27.904130 2016] [wsgi:error] [pid 10085:tid 140490608477952] [client 71.42.119.84:63924]   File "/usr/local/lib/python3.5/dist-packages/flask/app.py", line 1639, in full_dispatch_request
[Thu Nov 03 06:40:27.904135 2016] [wsgi:error] [pid 10085:tid 140490608477952] [client 71.42.119.84:63924]     rv = self.dispatch_request()
[Thu Nov 03 06:40:27.904140 2016] [wsgi:error] [pid 10085:tid 140490608477952] [client 71.42.119.84:63924]   File "/usr/local/lib/python3.5/dist-packages/flask/app.py", line 1625, in dispatch_request
[Thu Nov 03 06:40:27.904146 2016] [wsgi:error] [pid 10085:tid 140490608477952] [client 71.42.119.84:63924]     return self.view_functions[rule.endpoint](**req.view_args)
[Thu Nov 03 06:40:27.904151 2016] [wsgi:error] [pid 10085:tid 140490608477952] [client 71.42.119.84:63924]   File "/var/www/cs373f-idb/app/app.py", line 250, in api_platforms_id
[Thu Nov 03 06:40:27.904156 2016] [wsgi:error] [pid 10085:tid 140490608477952] [client 71.42.119.84:63924]     return jsonify(Platform.query.get(id).serialize())
[Thu Nov 03 06:40:27.904164 2016] [wsgi:error] [pid 10085:tid 140490608477952] [client 71.42.119.84:63924] AttributeError: 'NoneType' object has no attribute 'serialize'
[Thu Nov 03 06:40:27.904197 2016] [wsgi:error] [pid 10085:tid 140490608477952] [client 71.42.119.84:63924] 
[Thu Nov 03 06:40:44.195826 2016] [wsgi:error] [pid 10054:tid 140490452199168] [client 71.42.119.84:64412] [2016-11-03 06:40:44,195] ERROR in app: Exception on /api/platforms/44 [GET]
[Thu Nov 03 06:40:44.195877 2016] [wsgi:error] [pid 10054:tid 140490452199168] [client 71.42.119.84:64412] Traceback (most recent call last):
[Thu Nov 03 06:40:44.195883 2016] [wsgi:error] [pid 10054:tid 140490452199168] [client 71.42.119.84:64412]   File "/usr/local/lib/python3.5/dist-packages/flask/app.py", line 1988, in wsgi_app
[Thu Nov 03 06:40:44.195928 2016] [wsgi:error] [pid 10054:tid 140490452199168] [client 71.42.119.84:64412]     response = self.full_dispatch_request()
[Thu Nov 03 06:40:44.195937 2016] [wsgi:error] [pid 10054:tid 140490452199168] [client 71.42.119.84:64412]   File "/usr/local/lib/python3.5/dist-packages/flask/app.py", line 1641, in full_dispatch_request
[Thu Nov 03 06:40:44.195943 2016] [wsgi:error] [pid 10054:tid 140490452199168] [client 71.42.119.84:64412]     rv = self.handle_user_exception(e)
[Thu Nov 03 06:40:44.195948 2016] [wsgi:error] [pid 10054:tid 140490452199168] [client 71.42.119.84:64412]   File "/usr/local/lib/python3.5/dist-packages/flask/app.py", line 1544, in handle_user_exception
[Thu Nov 03 06:40:44.195953 2016] [wsgi:error] [pid 10054:tid 140490452199168] [client 71.42.119.84:64412]     reraise(exc_type, exc_value, tb)
[Thu Nov 03 06:40:44.195958 2016] [wsgi:error] [pid 10054:tid 140490452199168] [client 71.42.119.84:64412]   File "/usr/local/lib/python3.5/dist-packages/flask/_compat.py", line 33, in reraise
[Thu Nov 03 06:40:44.195963 2016] [wsgi:error] [pid 10054:tid 140490452199168] [client 71.42.119.84:64412]     raise value
[Thu Nov 03 06:40:44.195992 2016] [wsgi:error] [pid 10054:tid 140490452199168] [client 71.42.119.84:64412]   File "/usr/local/lib/python3.5/dist-packages/flask/app.py", line 1639, in full_dispatch_request
[Thu Nov 03 06:40:44.195999 2016] [wsgi:error] [pid 10054:tid 140490452199168] [client 71.42.119.84:64412]     rv = self.dispatch_request()
[Thu Nov 03 06:40:44.196004 2016] [wsgi:error] [pid 10054:tid 140490452199168] [client 71.42.119.84:64412]   File "/usr/local/lib/python3.5/dist-packages/flask/app.py", line 1625, in dispatch_request
[Thu Nov 03 06:40:44.196009 2016] [wsgi:error] [pid 10054:tid 140490452199168] [client 71.42.119.84:64412]     return self.view_functions[rule.endpoint](**req.view_args)
[Thu Nov 03 06:40:44.196014 2016] [wsgi:error] [pid 10054:tid 140490452199168] [client 71.42.119.84:64412]   File "/var/www/cs373f-idb/app/app.py", line 250, in api_platforms_id
[Thu Nov 03 06:40:44.196020 2016] [wsgi:error] [pid 10054:tid 140490452199168] [client 71.42.119.84:64412]     return jsonify(Platform.query.get(id).serialize())
[Thu Nov 03 06:40:44.196029 2016] [wsgi:error] [pid 10054:tid 140490452199168] [client 71.42.119.84:64412] AttributeError: 'NoneType' object has no attribute 'serialize'
[Thu Nov 03 06:40:44.196064 2016] [wsgi:error] [pid 10054:tid 140490452199168] [client 71.42.119.84:64412] 
[Thu Nov 03 16:15:19.191495 2016] [wsgi:error] [pid 15111:tid 140158338856704] [client 128.62.61.39:11759] [2016-11-03 16:15:19,186] ERROR in app: Exception on /getPlatform/ [GET], referer: http://vgidb.me/
[Thu Nov 03 16:15:19.191739 2016] [wsgi:error] [pid 15111:tid 140158338856704] [client 128.62.61.39:11759] Traceback (most recent call last):, referer: http://vgidb.me/
[Thu Nov 03 16:15:19.191753 2016] [wsgi:error] [pid 15111:tid 140158338856704] [client 128.62.61.39:11759]   File "/usr/local/lib/python3.5/dist-packages/flask/app.py", line 1988, in wsgi_app, referer: http://vgidb.me/
[Thu Nov 03 16:15:19.191760 2016] [wsgi:error] [pid 15111:tid 140158338856704] [client 128.62.61.39:11759]     response = self.full_dispatch_request(), referer: http://vgidb.me/
[Thu Nov 03 16:15:19.191767 2016] [wsgi:error] [pid 15111:tid 140158338856704] [client 128.62.61.39:11759]   File "/usr/local/lib/python3.5/dist-packages/flask/app.py", line 1641, in full_dispatch_request, referer: http://vgidb.me/
[Thu Nov 03 16:15:19.191773 2016] [wsgi:error] [pid 15111:tid 140158338856704] [client 128.62.61.39:11759]     rv = self.handle_user_exception(e), referer: http://vgidb.me/
[Thu Nov 03 16:15:19.191779 2016] [wsgi:error] [pid 15111:tid 140158338856704] [client 128.62.61.39:11759]   File "/usr/local/lib/python3.5/dist-packages/flask/app.py", line 1544, in handle_user_exception, referer: http://vgidb.me/
[Thu Nov 03 16:15:19.191785 2016] [wsgi:error] [pid 15111:tid 140158338856704] [client 128.62.61.39:11759]     reraise(exc_type, exc_value, tb), referer: http://vgidb.me/
[Thu Nov 03 16:15:19.191791 2016] [wsgi:error] [pid 15111:tid 140158338856704] [client 128.62.61.39:11759]   File "/usr/local/lib/python3.5/dist-packages/flask/_compat.py", line 33, in reraise, referer: http://vgidb.me/
[Thu Nov 03 16:15:19.191797 2016] [wsgi:error] [pid 15111:tid 140158338856704] [client 128.62.61.39:11759]     raise value, referer: http://vgidb.me/
[Thu Nov 03 16:15:19.191802 2016] [wsgi:error] [pid 15111:tid 140158338856704] [client 128.62.61.39:11759]   File "/usr/local/lib/python3.5/dist-packages/flask/app.py", line 1639, in full_dispatch_request, referer: http://vgidb.me/
[Thu Nov 03 16:15:19.191808 2016] [wsgi:error] [pid 15111:tid 140158338856704] [client 128.62.61.39:11759]     rv = self.dispatch_request(), referer: http://vgidb.me/
[Thu Nov 03 16:15:19.191814 2016] [wsgi:error] [pid 15111:tid 140158338856704] [client 128.62.61.39:11759]   File "/usr/local/lib/python3.5/dist-packages/flask/app.py", line 1625, in dispatch_request, referer: http://vgidb.me/
[Thu Nov 03 16:15:19.191820 2016] [wsgi:error] [pid 15111:tid 140158338856704] [client 128.62.61.39:11759]     return self.view_functions[rule.endpoint](**req.view_args), referer: http://vgidb.me/
[Thu Nov 03 16:15:19.191840 2016] [wsgi:error] [pid 15111:tid 140158338856704] [client 128.62.61.39:11759]   File "/var/www/cs373f-idb/app/app.py", line 161, in getPlatform, referer: http://vgidb.me/
[Thu Nov 03 16:15:19.191847 2016] [wsgi:error] [pid 15111:tid 140158338856704] [client 128.62.61.39:11759]     obj = jsonify(platformDict[platform_id]), referer: http://vgidb.me/
[Thu Nov 03 16:15:19.191858 2016] [wsgi:error] [pid 15111:tid 140158338856704] [client 128.62.61.39:11759] KeyError: 1, referer: http://vgidb.me/
[Thu Nov 03 16:15:19.191941 2016] [wsgi:error] [pid 15111:tid 140158338856704] [client 128.62.61.39:11759] , referer: http://vgidb.me/
[Thu Nov 03 16:15:19.989815 2016] [wsgi:error] [pid 15142:tid 140158288500480] [client 128.62.61.39:13041] [2016-11-03 16:15:19,988] ERROR in app: Exception on /getPlatform/ [GET], referer: http://vgidb.me/
[Thu Nov 03 16:15:19.989862 2016] [wsgi:error] [pid 15142:tid 140158288500480] [client 128.62.61.39:13041] Traceback (most recent call last):, referer: http://vgidb.me/
[Thu Nov 03 16:15:19.989868 2016] [wsgi:error] [pid 15142:tid 140158288500480] [client 128.62.61.39:13041]   File "/usr/local/lib/python3.5/dist-packages/flask/app.py", line 1988, in wsgi_app, referer: http://vgidb.me/
[Thu Nov 03 16:15:19.989874 2016] [wsgi:error] [pid 15142:tid 140158288500480] [client 128.62.61.39:13041]     response = self.full_dispatch_request(), referer: http://vgidb.me/
[Thu Nov 03 16:15:19.989880 2016] [wsgi:error] [pid 15142:tid 140158288500480] [client 128.62.61.39:13041]   File "/usr/local/lib/python3.5/dist-packages/flask/app.py", line 1641, in full_dispatch_request, referer: http://vgidb.me/
[Thu Nov 03 16:15:19.989886 2016] [wsgi:error] [pid 15142:tid 140158288500480] [client 128.62.61.39:13041]     rv = self.handle_user_exception(e), referer: http://vgidb.me/
[Thu Nov 03 16:15:19.989892 2016] [wsgi:error] [pid 15142:tid 140158288500480] [client 128.62.61.39:13041]   File "/usr/local/lib/python3.5/dist-packages/flask/app.py", line 1544, in handle_user_exception, referer: http://vgidb.me/
[Thu Nov 03 16:15:19.989897 2016] [wsgi:error] [pid 15142:tid 140158288500480] [client 128.62.61.39:13041]     reraise(exc_type, exc_value, tb), referer: http://vgidb.me/
[Thu Nov 03 16:15:19.989903 2016] [wsgi:error] [pid 15142:tid 140158288500480] [client 128.62.61.39:13041]   File "/usr/local/lib/python3.5/dist-packages/flask/_compat.py", line 33, in reraise, referer: http://vgidb.me/
[Thu Nov 03 16:15:19.989909 2016] [wsgi:error] [pid 15142:tid 140158288500480] [client 128.62.61.39:13041]     raise value, referer: http://vgidb.me/
[Thu Nov 03 16:15:19.989914 2016] [wsgi:error] [pid 15142:tid 140158288500480] [client 128.62.61.39:13041]   File "/usr/local/lib/python3.5/dist-packages/flask/app.py", line 1639, in full_dispatch_request, referer: http://vgidb.me/
[Thu Nov 03 16:15:19.989920 2016] [wsgi:error] [pid 15142:tid 140158288500480] [client 128.62.61.39:13041]     rv = self.dispatch_request(), referer: http://vgidb.me/
[Thu Nov 03 16:15:19.989925 2016] [wsgi:error] [pid 15142:tid 140158288500480] [client 128.62.61.39:13041]   File "/usr/local/lib/python3.5/dist-packages/flask/app.py", line 1625, in dispatch_request, referer: http://vgidb.me/
[Thu Nov 03 16:15:19.989931 2016] [wsgi:error] [pid 15142:tid 140158288500480] [client 128.62.61.39:13041]     return self.view_functions[rule.endpoint](**req.view_args), referer: http://vgidb.me/
[Thu Nov 03 16:15:19.989937 2016] [wsgi:error] [pid 15142:tid 140158288500480] [client 128.62.61.39:13041]   File "/var/www/cs373f-idb/app/app.py", line 161, in getPlatform, referer: http://vgidb.me/
[Thu Nov 03 16:15:19.989943 2016] [wsgi:error] [pid 15142:tid 140158288500480] [client 128.62.61.39:13041]     obj = jsonify(platformDict[platform_id]), referer: http://vgidb.me/
[Thu Nov 03 16:15:19.989951 2016] [wsgi:error] [pid 15142:tid 140158288500480] [client 128.62.61.39:13041] KeyError: 1, referer: http://vgidb.me/
[Thu Nov 03 16:15:19.989980 2016] [wsgi:error] [pid 15142:tid 140158288500480] [client 128.62.61.39:13041] , referer: http://vgidb.me/
[Thu Nov 03 16:51:23.822843 2016] [wsgi:error] [pid 15856:tid 140681007834880] [client 128.62.61.39:13095] [2016-11-03 16:51:23,820] ERROR in app: Exception on /api/platforms/offset/1 [GET], referer: http://vgidb.me/
[Thu Nov 03 16:51:23.823220 2016] [wsgi:error] [pid 15856:tid 140681007834880] [client 128.62.61.39:13095] Traceback (most recent call last):, referer: http://vgidb.me/
[Thu Nov 03 16:51:23.823235 2016] [wsgi:error] [pid 15856:tid 140681007834880] [client 128.62.61.39:13095]   File "/usr/local/lib/python3.5/dist-packages/flask/app.py", line 1988, in wsgi_app, referer: http://vgidb.me/
[Thu Nov 03 16:51:23.823241 2016] [wsgi:error] [pid 15856:tid 140681007834880] [client 128.62.61.39:13095]     response = self.full_dispatch_request(), referer: http://vgidb.me/
[Thu Nov 03 16:51:23.823247 2016] [wsgi:error] [pid 15856:tid 140681007834880] [client 128.62.61.39:13095]   File "/usr/local/lib/python3.5/dist-packages/flask/app.py", line 1641, in full_dispatch_request, referer: http://vgidb.me/
[Thu Nov 03 16:51:23.823252 2016] [wsgi:error] [pid 15856:tid 140681007834880] [client 128.62.61.39:13095]     rv = self.handle_user_exception(e), referer: http://vgidb.me/
[Thu Nov 03 16:51:23.823258 2016] [wsgi:error] [pid 15856:tid 140681007834880] [client 128.62.61.39:13095]   File "/usr/local/lib/python3.5/dist-packages/flask/app.py", line 1544, in handle_user_exception, referer: http://vgidb.me/
[Thu Nov 03 16:51:23.823263 2016] [wsgi:error] [pid 15856:tid 140681007834880] [client 128.62.61.39:13095]     reraise(exc_type, exc_value, tb), referer: http://vgidb.me/
[Thu Nov 03 16:51:23.823268 2016] [wsgi:error] [pid 15856:tid 140681007834880] [client 128.62.61.39:13095]   File "/usr/local/lib/python3.5/dist-packages/flask/_compat.py", line 33, in reraise, referer: http://vgidb.me/
[Thu Nov 03 16:51:23.823274 2016] [wsgi:error] [pid 15856:tid 140681007834880] [client 128.62.61.39:13095]     raise value, referer: http://vgidb.me/
[Thu Nov 03 16:51:23.823279 2016] [wsgi:error] [pid 15856:tid 140681007834880] [client 128.62.61.39:13095]   File "/usr/local/lib/python3.5/dist-packages/flask/app.py", line 1639, in full_dispatch_request, referer: http://vgidb.me/
[Thu Nov 03 16:51:23.823284 2016] [wsgi:error] [pid 15856:tid 140681007834880] [client 128.62.61.39:13095]     rv = self.dispatch_request(), referer: http://vgidb.me/
[Thu Nov 03 16:51:23.823290 2016] [wsgi:error] [pid 15856:tid 140681007834880] [client 128.62.61.39:13095]   File "/usr/local/lib/python3.5/dist-packages/flask/app.py", line 1625, in dispatch_request, referer: http://vgidb.me/
[Thu Nov 03 16:51:23.823295 2016] [wsgi:error] [pid 15856:tid 140681007834880] [client 128.62.61.39:13095]     return self.view_functions[rule.endpoint](**req.view_args), referer: http://vgidb.me/
[Thu Nov 03 16:51:23.823300 2016] [wsgi:error] [pid 15856:tid 140681007834880] [client 128.62.61.39:13095]   File "/var/www/cs373f-idb/app/app.py", line 236, in api_platforms_offset, referer: http://vgidb.me/
[Thu Nov 03 16:51:23.823306 2016] [wsgi:error] [pid 15856:tid 140681007834880] [client 128.62.61.39:13095]     dict_p[data.name] = data.serialize_table(), referer: http://vgidb.me/
[Thu Nov 03 16:51:23.823311 2016] [wsgi:error] [pid 15856:tid 140681007834880] [client 128.62.61.39:13095]   File "/var/www/cs373f-idb/app/models.py", line 135, in serialize_table, referer: http://vgidb.me/
[Thu Nov 03 16:51:23.823317 2016] [wsgi:error] [pid 15856:tid 140681007834880] [client 128.62.61.39:13095]     return {"name": self.name, "release_date": self.release_date, "company": self.company, "starting_price": self.start_price, "tiny_image": self.tiny_image}, referer: http://vgidb.me/
[Thu Nov 03 16:51:23.823327 2016] [wsgi:error] [pid 15856:tid 140681007834880] [client 128.62.61.39:13095] AttributeError: 'Platform' object has no attribute 'start_price', referer: http://vgidb.me/
[Thu Nov 03 16:51:23.823368 2016] [wsgi:error] [pid 15856:tid 140681007834880] [client 128.62.61.39:13095] , referer: http://vgidb.me/
[Thu Nov 03 16:51:24.832954 2016] [wsgi:error] [pid 15885:tid 140681007834880] [client 128.62.61.39:9400] [2016-11-03 16:51:24,831] ERROR in app: Exception on /api/platforms/offset/1 [GET], referer: http://vgidb.me/
[Thu Nov 03 16:51:24.833016 2016] [wsgi:error] [pid 15885:tid 140681007834880] [client 128.62.61.39:9400] Traceback (most recent call last):, referer: http://vgidb.me/
[Thu Nov 03 16:51:24.833024 2016] [wsgi:error] [pid 15885:tid 140681007834880] [client 128.62.61.39:9400]   File "/usr/local/lib/python3.5/dist-packages/flask/app.py", line 1988, in wsgi_app, referer: http://vgidb.me/
[Thu Nov 03 16:51:24.833030 2016] [wsgi:error] [pid 15885:tid 140681007834880] [client 128.62.61.39:9400]     response = self.full_dispatch_request(), referer: http://vgidb.me/
[Thu Nov 03 16:51:24.833035 2016] [wsgi:error] [pid 15885:tid 140681007834880] [client 128.62.61.39:9400]   File "/usr/local/lib/python3.5/dist-packages/flask/app.py", line 1641, in full_dispatch_request, referer: http://vgidb.me/
[Thu Nov 03 16:51:24.833041 2016] [wsgi:error] [pid 15885:tid 140681007834880] [client 128.62.61.39:9400]     rv = self.handle_user_exception(e), referer: http://vgidb.me/
[Thu Nov 03 16:51:24.833046 2016] [wsgi:error] [pid 15885:tid 140681007834880] [client 128.62.61.39:9400]   File "/usr/local/lib/python3.5/dist-packages/flask/app.py", line 1544, in handle_user_exception, referer: http://vgidb.me/
[Thu Nov 03 16:51:24.833051 2016] [wsgi:error] [pid 15885:tid 140681007834880] [client 128.62.61.39:9400]     reraise(exc_type, exc_value, tb), referer: http://vgidb.me/
[Thu Nov 03 16:51:24.833056 2016] [wsgi:error] [pid 15885:tid 140681007834880] [client 128.62.61.39:9400]   File "/usr/local/lib/python3.5/dist-packages/flask/_compat.py", line 33, in reraise, referer: http://vgidb.me/
[Thu Nov 03 16:51:24.833061 2016] [wsgi:error] [pid 15885:tid 140681007834880] [client 128.62.61.39:9400]     raise value, referer: http://vgidb.me/
[Thu Nov 03 16:51:24.833066 2016] [wsgi:error] [pid 15885:tid 140681007834880] [client 128.62.61.39:9400]   File "/usr/local/lib/python3.5/dist-packages/flask/app.py", line 1639, in full_dispatch_request, referer: http://vgidb.me/
[Thu Nov 03 16:51:24.833071 2016] [wsgi:error] [pid 15885:tid 140681007834880] [client 128.62.61.39:9400]     rv = self.dispatch_request(), referer: http://vgidb.me/
[Thu Nov 03 16:51:24.833076 2016] [wsgi:error] [pid 15885:tid 140681007834880] [client 128.62.61.39:9400]   File "/usr/local/lib/python3.5/dist-packages/flask/app.py", line 1625, in dispatch_request, referer: http://vgidb.me/
[Thu Nov 03 16:51:24.833081 2016] [wsgi:error] [pid 15885:tid 140681007834880] [client 128.62.61.39:9400]     return self.view_functions[rule.endpoint](**req.view_args), referer: http://vgidb.me/
[Thu Nov 03 16:51:24.833086 2016] [wsgi:error] [pid 15885:tid 140681007834880] [client 128.62.61.39:9400]   File "/var/www/cs373f-idb/app/app.py", line 236, in api_platforms_offset, referer: http://vgidb.me/
[Thu Nov 03 16:51:24.833091 2016] [wsgi:error] [pid 15885:tid 140681007834880] [client 128.62.61.39:9400]     dict_p[data.name] = data.serialize_table(), referer: http://vgidb.me/
[Thu Nov 03 16:51:24.833096 2016] [wsgi:error] [pid 15885:tid 140681007834880] [client 128.62.61.39:9400]   File "/var/www/cs373f-idb/app/models.py", line 135, in serialize_table, referer: http://vgidb.me/
[Thu Nov 03 16:51:24.833101 2016] [wsgi:error] [pid 15885:tid 140681007834880] [client 128.62.61.39:9400]     return {"name": self.name, "release_date": self.release_date, "company": self.company, "starting_price": self.start_price, "tiny_image": self.tiny_image}, referer: http://vgidb.me/
[Thu Nov 03 16:51:24.833109 2016] [wsgi:error] [pid 15885:tid 140681007834880] [client 128.62.61.39:9400] AttributeError: 'Platform' object has no attribute 'start_price', referer: http://vgidb.me/
[Thu Nov 03 16:51:24.833141 2016] [wsgi:error] [pid 15885:tid 140681007834880] [client 128.62.61.39:9400] , referer: http://vgidb.me/
[Thu Nov 03 16:56:17.189156 2016] [wsgi:error] [pid 16168:tid 139791012792064] [client 128.62.61.39:10567] [2016-11-03 16:56:17,186] ERROR in app: Exception on /api/characters/offset/1 [GET], referer: http://vgidb.me/
[Thu Nov 03 16:56:17.189563 2016] [wsgi:error] [pid 16168:tid 139791012792064] [client 128.62.61.39:10567] Traceback (most recent call last):, referer: http://vgidb.me/
[Thu Nov 03 16:56:17.189579 2016] [wsgi:error] [pid 16168:tid 139791012792064] [client 128.62.61.39:10567]   File "/usr/local/lib/python3.5/dist-packages/flask/app.py", line 1988, in wsgi_app, referer: http://vgidb.me/
[Thu Nov 03 16:56:17.189592 2016] [wsgi:error] [pid 16168:tid 139791012792064] [client 128.62.61.39:10567]     response = self.full_dispatch_request(), referer: http://vgidb.me/
[Thu Nov 03 16:56:17.189603 2016] [wsgi:error] [pid 16168:tid 139791012792064] [client 128.62.61.39:10567]   File "/usr/local/lib/python3.5/dist-packages/flask/app.py", line 1641, in full_dispatch_request, referer: http://vgidb.me/
[Thu Nov 03 16:56:17.189609 2016] [wsgi:error] [pid 16168:tid 139791012792064] [client 128.62.61.39:10567]     rv = self.handle_user_exception(e), referer: http://vgidb.me/
[Thu Nov 03 16:56:17.189614 2016] [wsgi:error] [pid 16168:tid 139791012792064] [client 128.62.61.39:10567]   File "/usr/local/lib/python3.5/dist-packages/flask/app.py", line 1544, in handle_user_exception, referer: http://vgidb.me/
[Thu Nov 03 16:56:17.189619 2016] [wsgi:error] [pid 16168:tid 139791012792064] [client 128.62.61.39:10567]     reraise(exc_type, exc_value, tb), referer: http://vgidb.me/
[Thu Nov 03 16:56:17.189624 2016] [wsgi:error] [pid 16168:tid 139791012792064] [client 128.62.61.39:10567]   File "/usr/local/lib/python3.5/dist-packages/flask/_compat.py", line 33, in reraise, referer: http://vgidb.me/
[Thu Nov 03 16:56:17.189629 2016] [wsgi:error] [pid 16168:tid 139791012792064] [client 128.62.61.39:10567]     raise value, referer: http://vgidb.me/
[Thu Nov 03 16:56:17.189634 2016] [wsgi:error] [pid 16168:tid 139791012792064] [client 128.62.61.39:10567]   File "/usr/local/lib/python3.5/dist-packages/flask/app.py", line 1639, in full_dispatch_request, referer: http://vgidb.me/
[Thu Nov 03 16:56:17.189639 2016] [wsgi:error] [pid 16168:tid 139791012792064] [client 128.62.61.39:10567]     rv = self.dispatch_request(), referer: http://vgidb.me/
[Thu Nov 03 16:56:17.189645 2016] [wsgi:error] [pid 16168:tid 139791012792064] [client 128.62.61.39:10567]   File "/usr/local/lib/python3.5/dist-packages/flask/app.py", line 1625, in dispatch_request, referer: http://vgidb.me/
[Thu Nov 03 16:56:17.189656 2016] [wsgi:error] [pid 16168:tid 139791012792064] [client 128.62.61.39:10567]     return self.view_functions[rule.endpoint](**req.view_args), referer: http://vgidb.me/
[Thu Nov 03 16:56:17.189667 2016] [wsgi:error] [pid 16168:tid 139791012792064] [client 128.62.61.39:10567]   File "/var/www/cs373f-idb/app/app.py", line 214, in api_characters_offset, referer: http://vgidb.me/
[Thu Nov 03 16:56:17.189673 2016] [wsgi:error] [pid 16168:tid 139791012792064] [client 128.62.61.39:10567]     dict_p[data.name] = data.serialize_table(), referer: http://vgidb.me/
[Thu Nov 03 16:56:17.189678 2016] [wsgi:error] [pid 16168:tid 139791012792064] [client 128.62.61.39:10567]   File "/var/www/cs373f-idb/app/models.py", line 173, in serialize_table, referer: http://vgidb.me/
[Thu Nov 03 16:56:17.189683 2016] [wsgi:error] [pid 16168:tid 139791012792064] [client 128.62.61.39:10567]     fields = {"name": self.name, "release_date": self.release_data, "platform": self.platform, "deck": self.deck, "tiny_image": self.tiny_image}, referer: http://vgidb.me/
[Thu Nov 03 16:56:17.189695 2016] [wsgi:error] [pid 16168:tid 139791012792064] [client 128.62.61.39:10567] AttributeError: 'Character' object has no attribute 'release_data', referer: http://vgidb.me/
[Thu Nov 03 16:56:17.189743 2016] [wsgi:error] [pid 16168:tid 139791012792064] [client 128.62.61.39:10567] , referer: http://vgidb.me/
[Thu Nov 03 16:59:02.103011 2016] [wsgi:error] [pid 16329:tid 139713180583680] [client 128.62.61.39:12566] [2016-11-03 16:59:02,099] ERROR in app: Exception on /api/characters/offset/1 [GET], referer: http://vgidb.me/
[Thu Nov 03 16:59:02.103228 2016] [wsgi:error] [pid 16329:tid 139713180583680] [client 128.62.61.39:12566] Traceback (most recent call last):, referer: http://vgidb.me/
[Thu Nov 03 16:59:02.103264 2016] [wsgi:error] [pid 16329:tid 139713180583680] [client 128.62.61.39:12566]   File "/usr/local/lib/python3.5/dist-packages/flask/app.py", line 1988, in wsgi_app, referer: http://vgidb.me/
[Thu Nov 03 16:59:02.103272 2016] [wsgi:error] [pid 16329:tid 139713180583680] [client 128.62.61.39:12566]     response = self.full_dispatch_request(), referer: http://vgidb.me/
[Thu Nov 03 16:59:02.103279 2016] [wsgi:error] [pid 16329:tid 139713180583680] [client 128.62.61.39:12566]   File "/usr/local/lib/python3.5/dist-packages/flask/app.py", line 1641, in full_dispatch_request, referer: http://vgidb.me/
[Thu Nov 03 16:59:02.103284 2016] [wsgi:error] [pid 16329:tid 139713180583680] [client 128.62.61.39:12566]     rv = self.handle_user_exception(e), referer: http://vgidb.me/
[Thu Nov 03 16:59:02.103290 2016] [wsgi:error] [pid 16329:tid 139713180583680] [client 128.62.61.39:12566]   File "/usr/local/lib/python3.5/dist-packages/flask/app.py", line 1544, in handle_user_exception, referer: http://vgidb.me/
[Thu Nov 03 16:59:02.103295 2016] [wsgi:error] [pid 16329:tid 139713180583680] [client 128.62.61.39:12566]     reraise(exc_type, exc_value, tb), referer: http://vgidb.me/
[Thu Nov 03 16:59:02.103300 2016] [wsgi:error] [pid 16329:tid 139713180583680] [client 128.62.61.39:12566]   File "/usr/local/lib/python3.5/dist-packages/flask/_compat.py", line 33, in reraise, referer: http://vgidb.me/
[Thu Nov 03 16:59:02.103306 2016] [wsgi:error] [pid 16329:tid 139713180583680] [client 128.62.61.39:12566]     raise value, referer: http://vgidb.me/
[Thu Nov 03 16:59:02.103311 2016] [wsgi:error] [pid 16329:tid 139713180583680] [client 128.62.61.39:12566]   File "/usr/local/lib/python3.5/dist-packages/flask/app.py", line 1639, in full_dispatch_request, referer: http://vgidb.me/
[Thu Nov 03 16:59:02.103316 2016] [wsgi:error] [pid 16329:tid 139713180583680] [client 128.62.61.39:12566]     rv = self.dispatch_request(), referer: http://vgidb.me/
[Thu Nov 03 16:59:02.103321 2016] [wsgi:error] [pid 16329:tid 139713180583680] [client 128.62.61.39:12566]   File "/usr/local/lib/python3.5/dist-packages/flask/app.py", line 1625, in dispatch_request, referer: http://vgidb.me/
[Thu Nov 03 16:59:02.103327 2016] [wsgi:error] [pid 16329:tid 139713180583680] [client 128.62.61.39:12566]     return self.view_functions[rule.endpoint](**req.view_args), referer: http://vgidb.me/
[Thu Nov 03 16:59:02.103332 2016] [wsgi:error] [pid 16329:tid 139713180583680] [client 128.62.61.39:12566]   File "/var/www/cs373f-idb/app/app.py", line 214, in api_characters_offset, referer: http://vgidb.me/
[Thu Nov 03 16:59:02.103337 2016] [wsgi:error] [pid 16329:tid 139713180583680] [client 128.62.61.39:12566]     dict_p[data.name] = data.serialize_table(), referer: http://vgidb.me/
[Thu Nov 03 16:59:02.103341 2016] [wsgi:error] [pid 16329:tid 139713180583680] [client 128.62.61.39:12566]   File "/var/www/cs373f-idb/app/models.py", line 173, in serialize_table, referer: http://vgidb.me/
[Thu Nov 03 16:59:02.103347 2016] [wsgi:error] [pid 16329:tid 139713180583680] [client 128.62.61.39:12566]     fields = {"name": self.name, "release_date": self.release_date, "platform": self.platform, "deck": self.deck, "tiny_image": self.tiny_image}, referer: http://vgidb.me/
[Thu Nov 03 16:59:02.103358 2016] [wsgi:error] [pid 16329:tid 139713180583680] [client 128.62.61.39:12566] AttributeError: 'Character' object has no attribute 'release_date', referer: http://vgidb.me/
[Thu Nov 03 16:59:02.103406 2016] [wsgi:error] [pid 16329:tid 139713180583680] [client 128.62.61.39:12566] , referer: http://vgidb.me/
[Thu Nov 03 17:02:25.269568 2016] [wsgi:error] [pid 16499:tid 140559767295744] [client 128.62.61.39:9827] [2016-11-03 17:02:25,266] ERROR in app: Exception on /api/characters/offset/1 [GET], referer: http://vgidb.me/
[Thu Nov 03 17:02:25.269735 2016] [wsgi:error] [pid 16499:tid 140559767295744] [client 128.62.61.39:9827] Traceback (most recent call last):, referer: http://vgidb.me/
[Thu Nov 03 17:02:25.269769 2016] [wsgi:error] [pid 16499:tid 140559767295744] [client 128.62.61.39:9827]   File "/usr/local/lib/python3.5/dist-packages/flask/app.py", line 1988, in wsgi_app, referer: http://vgidb.me/
[Thu Nov 03 17:02:25.269776 2016] [wsgi:error] [pid 16499:tid 140559767295744] [client 128.62.61.39:9827]     response = self.full_dispatch_request(), referer: http://vgidb.me/
[Thu Nov 03 17:02:25.269782 2016] [wsgi:error] [pid 16499:tid 140559767295744] [client 128.62.61.39:9827]   File "/usr/local/lib/python3.5/dist-packages/flask/app.py", line 1641, in full_dispatch_request, referer: http://vgidb.me/
[Thu Nov 03 17:02:25.269787 2016] [wsgi:error] [pid 16499:tid 140559767295744] [client 128.62.61.39:9827]     rv = self.handle_user_exception(e), referer: http://vgidb.me/
[Thu Nov 03 17:02:25.269792 2016] [wsgi:error] [pid 16499:tid 140559767295744] [client 128.62.61.39:9827]   File "/usr/local/lib/python3.5/dist-packages/flask/app.py", line 1544, in handle_user_exception, referer: http://vgidb.me/
[Thu Nov 03 17:02:25.269797 2016] [wsgi:error] [pid 16499:tid 140559767295744] [client 128.62.61.39:9827]     reraise(exc_type, exc_value, tb), referer: http://vgidb.me/
[Thu Nov 03 17:02:25.269802 2016] [wsgi:error] [pid 16499:tid 140559767295744] [client 128.62.61.39:9827]   File "/usr/local/lib/python3.5/dist-packages/flask/_compat.py", line 33, in reraise, referer: http://vgidb.me/
[Thu Nov 03 17:02:25.269807 2016] [wsgi:error] [pid 16499:tid 140559767295744] [client 128.62.61.39:9827]     raise value, referer: http://vgidb.me/
[Thu Nov 03 17:02:25.269811 2016] [wsgi:error] [pid 16499:tid 140559767295744] [client 128.62.61.39:9827]   File "/usr/local/lib/python3.5/dist-packages/flask/app.py", line 1639, in full_dispatch_request, referer: http://vgidb.me/
[Thu Nov 03 17:02:25.269816 2016] [wsgi:error] [pid 16499:tid 140559767295744] [client 128.62.61.39:9827]     rv = self.dispatch_request(), referer: http://vgidb.me/
[Thu Nov 03 17:02:25.269821 2016] [wsgi:error] [pid 16499:tid 140559767295744] [client 128.62.61.39:9827]   File "/usr/local/lib/python3.5/dist-packages/flask/app.py", line 1625, in dispatch_request, referer: http://vgidb.me/
[Thu Nov 03 17:02:25.269826 2016] [wsgi:error] [pid 16499:tid 140559767295744] [client 128.62.61.39:9827]     return self.view_functions[rule.endpoint](**req.view_args), referer: http://vgidb.me/
[Thu Nov 03 17:02:25.269831 2016] [wsgi:error] [pid 16499:tid 140559767295744] [client 128.62.61.39:9827]   File "/var/www/cs373f-idb/app/app.py", line 214, in api_characters_offset, referer: http://vgidb.me/
[Thu Nov 03 17:02:25.269836 2016] [wsgi:error] [pid 16499:tid 140559767295744] [client 128.62.61.39:9827]     dict_p[data.name] = data.serialize_table(), referer: http://vgidb.me/
[Thu Nov 03 17:02:25.269841 2016] [wsgi:error] [pid 16499:tid 140559767295744] [client 128.62.61.39:9827]   File "/var/www/cs373f-idb/app/models.py", line 173, in serialize_table, referer: http://vgidb.me/
[Thu Nov 03 17:02:25.269846 2016] [wsgi:error] [pid 16499:tid 140559767295744] [client 128.62.61.39:9827]     fields = {"name": self.name, "aliases": self.aliases, "platform": self.platform, "deck": self.deck, "tiny_image": self.tiny_image}, referer: http://vgidb.me/
[Thu Nov 03 17:02:25.269855 2016] [wsgi:error] [pid 16499:tid 140559767295744] [client 128.62.61.39:9827] AttributeError: 'Character' object has no attribute 'platform', referer: http://vgidb.me/
[Thu Nov 03 17:02:25.269892 2016] [wsgi:error] [pid 16499:tid 140559767295744] [client 128.62.61.39:9827] , referer: http://vgidb.me/
[Thu Nov 03 17:03:24.199138 2016] [wsgi:error] [pid 16565:tid 140559649797888] [client 128.62.74.11:28208] [2016-11-03 17:03:24,195] ERROR in app: Exception on /api/characters/offset/1 [GET], referer: http://vgidb.me/
[Thu Nov 03 17:03:24.199628 2016] [wsgi:error] [pid 16565:tid 140559649797888] [client 128.62.74.11:28208] Traceback (most recent call last):, referer: http://vgidb.me/
[Thu Nov 03 17:03:24.199642 2016] [wsgi:error] [pid 16565:tid 140559649797888] [client 128.62.74.11:28208]   File "/usr/local/lib/python3.5/dist-packages/flask/app.py", line 1988, in wsgi_app, referer: http://vgidb.me/
[Thu Nov 03 17:03:24.199660 2016] [wsgi:error] [pid 16565:tid 140559649797888] [client 128.62.74.11:28208]     response = self.full_dispatch_request(), referer: http://vgidb.me/
[Thu Nov 03 17:03:24.199667 2016] [wsgi:error] [pid 16565:tid 140559649797888] [client 128.62.74.11:28208]   File "/usr/local/lib/python3.5/dist-packages/flask/app.py", line 1641, in full_dispatch_request, referer: http://vgidb.me/
[Thu Nov 03 17:03:24.199672 2016] [wsgi:error] [pid 16565:tid 140559649797888] [client 128.62.74.11:28208]     rv = self.handle_user_exception(e), referer: http://vgidb.me/
[Thu Nov 03 17:03:24.199677 2016] [wsgi:error] [pid 16565:tid 140559649797888] [client 128.62.74.11:28208]   File "/usr/local/lib/python3.5/dist-packages/flask/app.py", line 1544, in handle_user_exception, referer: http://vgidb.me/
[Thu Nov 03 17:03:24.199682 2016] [wsgi:error] [pid 16565:tid 140559649797888] [client 128.62.74.11:28208]     reraise(exc_type, exc_value, tb), referer: http://vgidb.me/
[Thu Nov 03 17:03:24.199687 2016] [wsgi:error] [pid 16565:tid 140559649797888] [client 128.62.74.11:28208]   File "/usr/local/lib/python3.5/dist-packages/flask/_compat.py", line 33, in reraise, referer: http://vgidb.me/
[Thu Nov 03 17:03:24.199692 2016] [wsgi:error] [pid 16565:tid 140559649797888] [client 128.62.74.11:28208]     raise value, referer: http://vgidb.me/
[Thu Nov 03 17:03:24.199696 2016] [wsgi:error] [pid 16565:tid 140559649797888] [client 128.62.74.11:28208]   File "/usr/local/lib/python3.5/dist-packages/flask/app.py", line 1639, in full_dispatch_request, referer: http://vgidb.me/
[Thu Nov 03 17:03:24.199701 2016] [wsgi:error] [pid 16565:tid 140559649797888] [client 128.62.74.11:28208]     rv = self.dispatch_request(), referer: http://vgidb.me/
[Thu Nov 03 17:03:24.199706 2016] [wsgi:error] [pid 16565:tid 140559649797888] [client 128.62.74.11:28208]   File "/usr/local/lib/python3.5/dist-packages/flask/app.py", line 1625, in dispatch_request, referer: http://vgidb.me/
[Thu Nov 03 17:03:24.199711 2016] [wsgi:error] [pid 16565:tid 140559649797888] [client 128.62.74.11:28208]     return self.view_functions[rule.endpoint](**req.view_args), referer: http://vgidb.me/
[Thu Nov 03 17:03:24.199716 2016] [wsgi:error] [pid 16565:tid 140559649797888] [client 128.62.74.11:28208]   File "/var/www/cs373f-idb/app/app.py", line 214, in api_characters_offset, referer: http://vgidb.me/
[Thu Nov 03 17:03:24.199721 2016] [wsgi:error] [pid 16565:tid 140559649797888] [client 128.62.74.11:28208]     dict_p[data.name] = data.serialize_table(), referer: http://vgidb.me/
[Thu Nov 03 17:03:24.199726 2016] [wsgi:error] [pid 16565:tid 140559649797888] [client 128.62.74.11:28208]   File "/var/www/cs373f-idb/app/models.py", line 173, in serialize_table, referer: http://vgidb.me/
[Thu Nov 03 17:03:24.199731 2016] [wsgi:error] [pid 16565:tid 140559649797888] [client 128.62.74.11:28208]     fields = {"name": self.name, "aliases": self.aliases, "platform": self.platform, "deck": self.deck, "tiny_image": self.tiny_image}, referer: http://vgidb.me/
[Thu Nov 03 17:03:24.199740 2016] [wsgi:error] [pid 16565:tid 140559649797888] [client 128.62.74.11:28208] AttributeError: 'Character' object has no attribute 'platform', referer: http://vgidb.me/
[Thu Nov 03 17:03:24.199780 2016] [wsgi:error] [pid 16565:tid 140559649797888] [client 128.62.74.11:28208] , referer: http://vgidb.me/
[Thu Nov 03 17:03:41.549545 2016] [wsgi:error] [pid 16640:tid 140559733724928] [client 128.62.74.11:28570] [2016-11-03 17:03:41,541] ERROR in app: Exception on /api/platforms/0 [GET], referer: http://vgidb.me/
[Thu Nov 03 17:03:41.553003 2016] [wsgi:error] [pid 16640:tid 140559733724928] [client 128.62.74.11:28570] Traceback (most recent call last):, referer: http://vgidb.me/
[Thu Nov 03 17:03:41.553020 2016] [wsgi:error] [pid 16640:tid 140559733724928] [client 128.62.74.11:28570]   File "/usr/local/lib/python3.5/dist-packages/flask/app.py", line 1988, in wsgi_app, referer: http://vgidb.me/
[Thu Nov 03 17:03:41.553027 2016] [wsgi:error] [pid 16640:tid 140559733724928] [client 128.62.74.11:28570]     response = self.full_dispatch_request(), referer: http://vgidb.me/
[Thu Nov 03 17:03:41.553048 2016] [wsgi:error] [pid 16640:tid 140559733724928] [client 128.62.74.11:28570]   File "/usr/local/lib/python3.5/dist-packages/flask/app.py", line 1641, in full_dispatch_request, referer: http://vgidb.me/
[Thu Nov 03 17:03:41.553054 2016] [wsgi:error] [pid 16640:tid 140559733724928] [client 128.62.74.11:28570]     rv = self.handle_user_exception(e), referer: http://vgidb.me/
[Thu Nov 03 17:03:41.553059 2016] [wsgi:error] [pid 16640:tid 140559733724928] [client 128.62.74.11:28570]   File "/usr/local/lib/python3.5/dist-packages/flask/app.py", line 1544, in handle_user_exception, referer: http://vgidb.me/
[Thu Nov 03 17:03:41.553064 2016] [wsgi:error] [pid 16640:tid 140559733724928] [client 128.62.74.11:28570]     reraise(exc_type, exc_value, tb), referer: http://vgidb.me/
[Thu Nov 03 17:03:41.553069 2016] [wsgi:error] [pid 16640:tid 140559733724928] [client 128.62.74.11:28570]   File "/usr/local/lib/python3.5/dist-packages/flask/_compat.py", line 33, in reraise, referer: http://vgidb.me/
[Thu Nov 03 17:03:41.553074 2016] [wsgi:error] [pid 16640:tid 140559733724928] [client 128.62.74.11:28570]     raise value, referer: http://vgidb.me/
[Thu Nov 03 17:03:41.553079 2016] [wsgi:error] [pid 16640:tid 140559733724928] [client 128.62.74.11:28570]   File "/usr/local/lib/python3.5/dist-packages/flask/app.py", line 1639, in full_dispatch_request, referer: http://vgidb.me/
[Thu Nov 03 17:03:41.553084 2016] [wsgi:error] [pid 16640:tid 140559733724928] [client 128.62.74.11:28570]     rv = self.dispatch_request(), referer: http://vgidb.me/
[Thu Nov 03 17:03:41.553089 2016] [wsgi:error] [pid 16640:tid 140559733724928] [client 128.62.74.11:28570]   File "/usr/local/lib/python3.5/dist-packages/flask/app.py", line 1625, in dispatch_request, referer: http://vgidb.me/
[Thu Nov 03 17:03:41.553094 2016] [wsgi:error] [pid 16640:tid 140559733724928] [client 128.62.74.11:28570]     return self.view_functions[rule.endpoint](**req.view_args), referer: http://vgidb.me/
[Thu Nov 03 17:03:41.553099 2016] [wsgi:error] [pid 16640:tid 140559733724928] [client 128.62.74.11:28570]   File "/var/www/cs373f-idb/app/app.py", line 245, in api_platforms_id, referer: http://vgidb.me/
[Thu Nov 03 17:03:41.553104 2016] [wsgi:error] [pid 16640:tid 140559733724928] [client 128.62.74.11:28570]     return jsonify(Platform.query.get(id).serialize()), referer: http://vgidb.me/
[Thu Nov 03 17:03:41.553115 2016] [wsgi:error] [pid 16640:tid 140559733724928] [client 128.62.74.11:28570] AttributeError: 'NoneType' object has no attribute 'serialize', referer: http://vgidb.me/
[Thu Nov 03 17:03:41.553169 2016] [wsgi:error] [pid 16640:tid 140559733724928] [client 128.62.74.11:28570] , referer: http://vgidb.me/
[Thu Nov 03 17:03:41.708227 2016] [wsgi:error] [pid 16640:tid 140559767295744] [client 128.62.74.11:27773] [2016-11-03 17:03:41,707] ERROR in app: Exception on /api/platforms/0 [GET], referer: http://vgidb.me/
[Thu Nov 03 17:03:41.708276 2016] [wsgi:error] [pid 16640:tid 140559767295744] [client 128.62.74.11:27773] Traceback (most recent call last):, referer: http://vgidb.me/
[Thu Nov 03 17:03:41.708282 2016] [wsgi:error] [pid 16640:tid 140559767295744] [client 128.62.74.11:27773]   File "/usr/local/lib/python3.5/dist-packages/flask/app.py", line 1988, in wsgi_app, referer: http://vgidb.me/
[Thu Nov 03 17:03:41.708288 2016] [wsgi:error] [pid 16640:tid 140559767295744] [client 128.62.74.11:27773]     response = self.full_dispatch_request(), referer: http://vgidb.me/
[Thu Nov 03 17:03:41.708293 2016] [wsgi:error] [pid 16640:tid 140559767295744] [client 128.62.74.11:27773]   File "/usr/local/lib/python3.5/dist-packages/flask/app.py", line 1641, in full_dispatch_request, referer: http://vgidb.me/
[Thu Nov 03 17:03:41.708298 2016] [wsgi:error] [pid 16640:tid 140559767295744] [client 128.62.74.11:27773]     rv = self.handle_user_exception(e), referer: http://vgidb.me/
[Thu Nov 03 17:03:41.708303 2016] [wsgi:error] [pid 16640:tid 140559767295744] [client 128.62.74.11:27773]   File "/usr/local/lib/python3.5/dist-packages/flask/app.py", line 1544, in handle_user_exception, referer: http://vgidb.me/
[Thu Nov 03 17:03:41.708335 2016] [wsgi:error] [pid 16640:tid 140559767295744] [client 128.62.74.11:27773]     reraise(exc_type, exc_value, tb), referer: http://vgidb.me/
[Thu Nov 03 17:03:41.708342 2016] [wsgi:error] [pid 16640:tid 140559767295744] [client 128.62.74.11:27773]   File "/usr/local/lib/python3.5/dist-packages/flask/_compat.py", line 33, in reraise, referer: http://vgidb.me/
[Thu Nov 03 17:03:41.708348 2016] [wsgi:error] [pid 16640:tid 140559767295744] [client 128.62.74.11:27773]     raise value, referer: http://vgidb.me/
[Thu Nov 03 17:03:41.708352 2016] [wsgi:error] [pid 16640:tid 140559767295744] [client 128.62.74.11:27773]   File "/usr/local/lib/python3.5/dist-packages/flask/app.py", line 1639, in full_dispatch_request, referer: http://vgidb.me/
[Thu Nov 03 17:03:41.708358 2016] [wsgi:error] [pid 16640:tid 140559767295744] [client 128.62.74.11:27773]     rv = self.dispatch_request(), referer: http://vgidb.me/
[Thu Nov 03 17:03:41.708363 2016] [wsgi:error] [pid 16640:tid 140559767295744] [client 128.62.74.11:27773]   File "/usr/local/lib/python3.5/dist-packages/flask/app.py", line 1625, in dispatch_request, referer: http://vgidb.me/
[Thu Nov 03 17:03:41.708368 2016] [wsgi:error] [pid 16640:tid 140559767295744] [client 128.62.74.11:27773]     return self.view_functions[rule.endpoint](**req.view_args), referer: http://vgidb.me/
[Thu Nov 03 17:03:41.708373 2016] [wsgi:error] [pid 16640:tid 140559767295744] [client 128.62.74.11:27773]   File "/var/www/cs373f-idb/app/app.py", line 245, in api_platforms_id, referer: http://vgidb.me/
[Thu Nov 03 17:03:41.708377 2016] [wsgi:error] [pid 16640:tid 140559767295744] [client 128.62.74.11:27773]     return jsonify(Platform.query.get(id).serialize()), referer: http://vgidb.me/
[Thu Nov 03 17:03:41.708385 2016] [wsgi:error] [pid 16640:tid 140559767295744] [client 128.62.74.11:27773] AttributeError: 'NoneType' object has no attribute 'serialize', referer: http://vgidb.me/
[Thu Nov 03 17:03:41.708418 2016] [wsgi:error] [pid 16640:tid 140559767295744] [client 128.62.74.11:27773] , referer: http://vgidb.me/
[Thu Nov 03 17:05:27.453077 2016] [wsgi:error] [pid 16830:tid 139936031778560] [client 128.62.61.39:12560] mod_wsgi (pid=16830): Target WSGI script '/var/www/cs373f-idb/app.wsgi' cannot be loaded as Python module.
[Thu Nov 03 17:05:27.453660 2016] [wsgi:error] [pid 16830:tid 139936031778560] [client 128.62.61.39:12560] mod_wsgi (pid=16830): Exception occurred processing WSGI script '/var/www/cs373f-idb/app.wsgi'.
[Thu Nov 03 17:05:27.454659 2016] [wsgi:error] [pid 16830:tid 139936031778560] [client 128.62.61.39:12560] Traceback (most recent call last):
[Thu Nov 03 17:05:27.454739 2016] [wsgi:error] [pid 16830:tid 139936031778560] [client 128.62.61.39:12560]   File "/var/www/cs373f-idb/app.wsgi", line 7, in <module>
[Thu Nov 03 17:05:27.454752 2016] [wsgi:error] [pid 16830:tid 139936031778560] [client 128.62.61.39:12560]     from app.app import app as application
[Thu Nov 03 17:05:27.454769 2016] [wsgi:error] [pid 16830:tid 139936031778560] [client 128.62.61.39:12560]   File "/var/www/cs373f-idb/app/app.py", line 8, in <module>
[Thu Nov 03 17:05:27.454777 2016] [wsgi:error] [pid 16830:tid 139936031778560] [client 128.62.61.39:12560]     from app.tests import runTestsOut
[Thu Nov 03 17:05:27.454791 2016] [wsgi:error] [pid 16830:tid 139936031778560] [client 128.62.61.39:12560]   File "/var/www/cs373f-idb/app/tests.py", line 4, in <module>
[Thu Nov 03 17:05:27.454799 2016] [wsgi:error] [pid 16830:tid 139936031778560] [client 128.62.61.39:12560]     from app.models \t\timport *
[Thu Nov 03 17:05:27.454835 2016] [wsgi:error] [pid 16830:tid 139936031778560] [client 128.62.61.39:12560]   File "/var/www/cs373f-idb/app/models.py", line 173
[Thu Nov 03 17:05:27.454860 2016] [wsgi:error] [pid 16830:tid 139936031778560] [client 128.62.61.39:12560]     fields = {"name": self.name, "aliases": self.aliases, "first_appeared_in_game":,self.first_appeared_in_game, "deck": self.deck, "tiny_image": self.tiny_image}
[Thu Nov 03 17:05:27.454955 2016] [wsgi:error] [pid 16830:tid 139936031778560] [client 128.62.61.39:12560]                                                                                    ^
[Thu Nov 03 17:05:27.454981 2016] [wsgi:error] [pid 16830:tid 139936031778560] [client 128.62.61.39:12560] SyntaxError: invalid syntax
[Thu Nov 03 17:09:35.194703 2016] [wsgi:error] [pid 16829:tid 139935914903296] [client 128.62.74.11:29048] mod_wsgi (pid=16829): Target WSGI script '/var/www/cs373f-idb/app.wsgi' cannot be loaded as Python module., referer: http://vgidb.me/
[Thu Nov 03 17:09:35.194877 2016] [wsgi:error] [pid 16829:tid 139935914903296] [client 128.62.74.11:29048] mod_wsgi (pid=16829): Exception occurred processing WSGI script '/var/www/cs373f-idb/app.wsgi'., referer: http://vgidb.me/
[Thu Nov 03 17:09:35.195752 2016] [wsgi:error] [pid 16829:tid 139935914903296] [client 128.62.74.11:29048] Traceback (most recent call last):, referer: http://vgidb.me/
[Thu Nov 03 17:09:35.195817 2016] [wsgi:error] [pid 16829:tid 139935914903296] [client 128.62.74.11:29048]   File "/var/www/cs373f-idb/app.wsgi", line 7, in <module>, referer: http://vgidb.me/
[Thu Nov 03 17:09:35.195830 2016] [wsgi:error] [pid 16829:tid 139935914903296] [client 128.62.74.11:29048]     from app.app import app as application, referer: http://vgidb.me/
[Thu Nov 03 17:09:35.195847 2016] [wsgi:error] [pid 16829:tid 139935914903296] [client 128.62.74.11:29048]   File "/var/www/cs373f-idb/app/app.py", line 8, in <module>, referer: http://vgidb.me/
[Thu Nov 03 17:09:35.195856 2016] [wsgi:error] [pid 16829:tid 139935914903296] [client 128.62.74.11:29048]     from app.tests import runTestsOut, referer: http://vgidb.me/
[Thu Nov 03 17:09:35.195870 2016] [wsgi:error] [pid 16829:tid 139935914903296] [client 128.62.74.11:29048]   File "/var/www/cs373f-idb/app/tests.py", line 4, in <module>, referer: http://vgidb.me/
[Thu Nov 03 17:09:35.195879 2016] [wsgi:error] [pid 16829:tid 139935914903296] [client 128.62.74.11:29048]     from app.models \t\timport *, referer: http://vgidb.me/
[Thu Nov 03 17:09:35.195962 2016] [wsgi:error] [pid 16829:tid 139935914903296] [client 128.62.74.11:29048]   File "/var/www/cs373f-idb/app/models.py", line 173, referer: http://vgidb.me/
[Thu Nov 03 17:09:35.195994 2016] [wsgi:error] [pid 16829:tid 139935914903296] [client 128.62.74.11:29048]     fields = {"name": self.name, "aliases": self.aliases, "first_appeared_in_game":,self.first_appeared_in_game, "deck": self.deck, "tiny_image": self.tiny_image}, referer: http://vgidb.me/
[Thu Nov 03 17:09:35.196060 2016] [wsgi:error] [pid 16829:tid 139935914903296] [client 128.62.74.11:29048]                                                                                    ^, referer: http://vgidb.me/
[Thu Nov 03 17:09:35.196085 2016] [wsgi:error] [pid 16829:tid 139935914903296] [client 128.62.74.11:29048] SyntaxError: invalid syntax, referer: http://vgidb.me/
[Thu Nov 03 17:09:37.859592 2016] [wsgi:error] [pid 16830:tid 139936023377664] [client 128.62.74.11:27223] mod_wsgi (pid=16830): Target WSGI script '/var/www/cs373f-idb/app.wsgi' cannot be loaded as Python module., referer: http://vgidb.me/
[Thu Nov 03 17:09:37.859803 2016] [wsgi:error] [pid 16830:tid 139936023377664] [client 128.62.74.11:27223] mod_wsgi (pid=16830): Exception occurred processing WSGI script '/var/www/cs373f-idb/app.wsgi'., referer: http://vgidb.me/
[Thu Nov 03 17:09:37.860348 2016] [wsgi:error] [pid 16830:tid 139936023377664] [client 128.62.74.11:27223] Traceback (most recent call last):, referer: http://vgidb.me/
[Thu Nov 03 17:09:37.860417 2016] [wsgi:error] [pid 16830:tid 139936023377664] [client 128.62.74.11:27223]   File "/var/www/cs373f-idb/app.wsgi", line 7, in <module>, referer: http://vgidb.me/
[Thu Nov 03 17:09:37.860431 2016] [wsgi:error] [pid 16830:tid 139936023377664] [client 128.62.74.11:27223]     from app.app import app as application, referer: http://vgidb.me/
[Thu Nov 03 17:09:37.860448 2016] [wsgi:error] [pid 16830:tid 139936023377664] [client 128.62.74.11:27223]   File "/var/www/cs373f-idb/app/app.py", line 8, in <module>, referer: http://vgidb.me/
[Thu Nov 03 17:09:37.860486 2016] [wsgi:error] [pid 16830:tid 139936023377664] [client 128.62.74.11:27223]     from app.tests import runTestsOut, referer: http://vgidb.me/
[Thu Nov 03 17:09:37.860517 2016] [wsgi:error] [pid 16830:tid 139936023377664] [client 128.62.74.11:27223]   File "/var/www/cs373f-idb/app/tests.py", line 4, in <module>, referer: http://vgidb.me/
[Thu Nov 03 17:09:37.860529 2016] [wsgi:error] [pid 16830:tid 139936023377664] [client 128.62.74.11:27223]     from app.models \t\timport *, referer: http://vgidb.me/
[Thu Nov 03 17:09:37.860572 2016] [wsgi:error] [pid 16830:tid 139936023377664] [client 128.62.74.11:27223]   File "/var/www/cs373f-idb/app/models.py", line 173, referer: http://vgidb.me/
[Thu Nov 03 17:09:37.860621 2016] [wsgi:error] [pid 16830:tid 139936023377664] [client 128.62.74.11:27223]     fields = {"name": self.name, "aliases": self.aliases, "first_appeared_in_game":,self.first_appeared_in_game, "deck": self.deck, "tiny_image": self.tiny_image}, referer: http://vgidb.me/
[Thu Nov 03 17:09:37.860719 2016] [wsgi:error] [pid 16830:tid 139936023377664] [client 128.62.74.11:27223]                                                                                    ^, referer: http://vgidb.me/
[Thu Nov 03 17:09:37.860745 2016] [wsgi:error] [pid 16830:tid 139936023377664] [client 128.62.74.11:27223] SyntaxError: invalid syntax, referer: http://vgidb.me/
[Thu Nov 03 17:09:37.980266 2016] [wsgi:error] [pid 16829:tid 139935940081408] [client 128.62.74.11:25859] mod_wsgi (pid=16829): Target WSGI script '/var/www/cs373f-idb/app.wsgi' cannot be loaded as Python module., referer: http://vgidb.me/
[Thu Nov 03 17:09:37.980471 2016] [wsgi:error] [pid 16829:tid 139935940081408] [client 128.62.74.11:25859] mod_wsgi (pid=16829): Exception occurred processing WSGI script '/var/www/cs373f-idb/app.wsgi'., referer: http://vgidb.me/
[Thu Nov 03 17:09:37.980746 2016] [wsgi:error] [pid 16829:tid 139935940081408] [client 128.62.74.11:25859] Traceback (most recent call last):, referer: http://vgidb.me/
[Thu Nov 03 17:09:37.980811 2016] [wsgi:error] [pid 16829:tid 139935940081408] [client 128.62.74.11:25859]   File "/var/www/cs373f-idb/app.wsgi", line 7, in <module>, referer: http://vgidb.me/
[Thu Nov 03 17:09:37.980823 2016] [wsgi:error] [pid 16829:tid 139935940081408] [client 128.62.74.11:25859]     from app.app import app as application, referer: http://vgidb.me/
[Thu Nov 03 17:09:37.980840 2016] [wsgi:error] [pid 16829:tid 139935940081408] [client 128.62.74.11:25859]   File "/var/www/cs373f-idb/app/app.py", line 8, in <module>, referer: http://vgidb.me/
[Thu Nov 03 17:09:37.980849 2016] [wsgi:error] [pid 16829:tid 139935940081408] [client 128.62.74.11:25859]     from app.tests import runTestsOut, referer: http://vgidb.me/
[Thu Nov 03 17:09:37.980863 2016] [wsgi:error] [pid 16829:tid 139935940081408] [client 128.62.74.11:25859]   File "/var/www/cs373f-idb/app/tests.py", line 4, in <module>, referer: http://vgidb.me/
[Thu Nov 03 17:09:37.980871 2016] [wsgi:error] [pid 16829:tid 139935940081408] [client 128.62.74.11:25859]     from app.models \t\timport *, referer: http://vgidb.me/
[Thu Nov 03 17:09:37.980901 2016] [wsgi:error] [pid 16829:tid 139935940081408] [client 128.62.74.11:25859]   File "/var/www/cs373f-idb/app/models.py", line 173, referer: http://vgidb.me/
[Thu Nov 03 17:09:37.980952 2016] [wsgi:error] [pid 16829:tid 139935940081408] [client 128.62.74.11:25859]     fields = {"name": self.name, "aliases": self.aliases, "first_appeared_in_game":,self.first_appeared_in_game, "deck": self.deck, "tiny_image": self.tiny_image}, referer: http://vgidb.me/
[Thu Nov 03 17:09:37.981042 2016] [wsgi:error] [pid 16829:tid 139935940081408] [client 128.62.74.11:25859]                                                                                    ^, referer: http://vgidb.me/
[Thu Nov 03 17:09:37.981068 2016] [wsgi:error] [pid 16829:tid 139935940081408] [client 128.62.74.11:25859] SyntaxError: invalid syntax, referer: http://vgidb.me/
[Thu Nov 03 17:09:40.056991 2016] [wsgi:error] [pid 16829:tid 139935931688704] [client 128.62.74.11:25924] mod_wsgi (pid=16829): Target WSGI script '/var/www/cs373f-idb/app.wsgi' cannot be loaded as Python module., referer: http://vgidb.me/
[Thu Nov 03 17:09:40.057158 2016] [wsgi:error] [pid 16829:tid 139935931688704] [client 128.62.74.11:25924] mod_wsgi (pid=16829): Exception occurred processing WSGI script '/var/www/cs373f-idb/app.wsgi'., referer: http://vgidb.me/
[Thu Nov 03 17:09:40.057384 2016] [wsgi:error] [pid 16829:tid 139935931688704] [client 128.62.74.11:25924] Traceback (most recent call last):, referer: http://vgidb.me/
[Thu Nov 03 17:09:40.057440 2016] [wsgi:error] [pid 16829:tid 139935931688704] [client 128.62.74.11:25924]   File "/var/www/cs373f-idb/app.wsgi", line 7, in <module>, referer: http://vgidb.me/
[Thu Nov 03 17:09:40.057452 2016] [wsgi:error] [pid 16829:tid 139935931688704] [client 128.62.74.11:25924]     from app.app import app as application, referer: http://vgidb.me/
[Thu Nov 03 17:09:40.057469 2016] [wsgi:error] [pid 16829:tid 139935931688704] [client 128.62.74.11:25924]   File "/var/www/cs373f-idb/app/app.py", line 8, in <module>, referer: http://vgidb.me/
[Thu Nov 03 17:09:40.057477 2016] [wsgi:error] [pid 16829:tid 139935931688704] [client 128.62.74.11:25924]     from app.tests import runTestsOut, referer: http://vgidb.me/
[Thu Nov 03 17:09:40.057491 2016] [wsgi:error] [pid 16829:tid 139935931688704] [client 128.62.74.11:25924]   File "/var/www/cs373f-idb/app/tests.py", line 4, in <module>, referer: http://vgidb.me/
[Thu Nov 03 17:09:40.057500 2016] [wsgi:error] [pid 16829:tid 139935931688704] [client 128.62.74.11:25924]     from app.models \t\timport *, referer: http://vgidb.me/
[Thu Nov 03 17:09:40.057528 2016] [wsgi:error] [pid 16829:tid 139935931688704] [client 128.62.74.11:25924]   File "/var/www/cs373f-idb/app/models.py", line 173, referer: http://vgidb.me/
[Thu Nov 03 17:09:40.057562 2016] [wsgi:error] [pid 16829:tid 139935931688704] [client 128.62.74.11:25924]     fields = {"name": self.name, "aliases": self.aliases, "first_appeared_in_game":,self.first_appeared_in_game, "deck": self.deck, "tiny_image": self.tiny_image}, referer: http://vgidb.me/
[Thu Nov 03 17:09:40.057628 2016] [wsgi:error] [pid 16829:tid 139935931688704] [client 128.62.74.11:25924]                                                                                    ^, referer: http://vgidb.me/
[Thu Nov 03 17:09:40.057651 2016] [wsgi:error] [pid 16829:tid 139935931688704] [client 128.62.74.11:25924] SyntaxError: invalid syntax, referer: http://vgidb.me/
[Thu Nov 03 17:09:40.172004 2016] [wsgi:error] [pid 16830:tid 139936040179456] [client 128.62.74.11:25925] mod_wsgi (pid=16830): Target WSGI script '/var/www/cs373f-idb/app.wsgi' cannot be loaded as Python module., referer: http://vgidb.me/
[Thu Nov 03 17:09:40.172166 2016] [wsgi:error] [pid 16830:tid 139936040179456] [client 128.62.74.11:25925] mod_wsgi (pid=16830): Exception occurred processing WSGI script '/var/www/cs373f-idb/app.wsgi'., referer: http://vgidb.me/
[Thu Nov 03 17:09:40.172418 2016] [wsgi:error] [pid 16830:tid 139936040179456] [client 128.62.74.11:25925] Traceback (most recent call last):, referer: http://vgidb.me/
[Thu Nov 03 17:09:40.172483 2016] [wsgi:error] [pid 16830:tid 139936040179456] [client 128.62.74.11:25925]   File "/var/www/cs373f-idb/app.wsgi", line 7, in <module>, referer: http://vgidb.me/
[Thu Nov 03 17:09:40.172495 2016] [wsgi:error] [pid 16830:tid 139936040179456] [client 128.62.74.11:25925]     from app.app import app as application, referer: http://vgidb.me/
[Thu Nov 03 17:09:40.172529 2016] [wsgi:error] [pid 16830:tid 139936040179456] [client 128.62.74.11:25925]   File "/var/www/cs373f-idb/app/app.py", line 8, in <module>, referer: http://vgidb.me/
[Thu Nov 03 17:09:40.172540 2016] [wsgi:error] [pid 16830:tid 139936040179456] [client 128.62.74.11:25925]     from app.tests import runTestsOut, referer: http://vgidb.me/
[Thu Nov 03 17:09:40.172555 2016] [wsgi:error] [pid 16830:tid 139936040179456] [client 128.62.74.11:25925]   File "/var/www/cs373f-idb/app/tests.py", line 4, in <module>, referer: http://vgidb.me/
[Thu Nov 03 17:09:40.172609 2016] [wsgi:error] [pid 16830:tid 139936040179456] [client 128.62.74.11:25925]     from app.models \t\timport *, referer: http://vgidb.me/
[Thu Nov 03 17:09:40.172651 2016] [wsgi:error] [pid 16830:tid 139936040179456] [client 128.62.74.11:25925]   File "/var/www/cs373f-idb/app/models.py", line 173, referer: http://vgidb.me/
[Thu Nov 03 17:09:40.172679 2016] [wsgi:error] [pid 16830:tid 139936040179456] [client 128.62.74.11:25925]     fields = {"name": self.name, "aliases": self.aliases, "first_appeared_in_game":,self.first_appeared_in_game, "deck": self.deck, "tiny_image": self.tiny_image}, referer: http://vgidb.me/
[Thu Nov 03 17:09:40.172753 2016] [wsgi:error] [pid 16830:tid 139936040179456] [client 128.62.74.11:25925]                                                                                    ^, referer: http://vgidb.me/
[Thu Nov 03 17:09:40.172777 2016] [wsgi:error] [pid 16830:tid 139936040179456] [client 128.62.74.11:25925] SyntaxError: invalid syntax, referer: http://vgidb.me/
[Thu Nov 03 17:13:46.634374 2016] [wsgi:error] [pid 17408:tid 140220548773632] [client 67.78.97.71:62452] [2016-11-03 17:13:46,632] ERROR in app: Exception on /api/games/offset/1 Failed to load resource: net::ERR_EMPTY_RESPONSE [GET]
[Thu Nov 03 17:13:46.635179 2016] [wsgi:error] [pid 17408:tid 140220548773632] [client 67.78.97.71:62452] Traceback (most recent call last):
[Thu Nov 03 17:13:46.635194 2016] [wsgi:error] [pid 17408:tid 140220548773632] [client 67.78.97.71:62452]   File "/usr/local/lib/python3.5/dist-packages/flask/app.py", line 1988, in wsgi_app
[Thu Nov 03 17:13:46.635201 2016] [wsgi:error] [pid 17408:tid 140220548773632] [client 67.78.97.71:62452]     response = self.full_dispatch_request()
[Thu Nov 03 17:13:46.635207 2016] [wsgi:error] [pid 17408:tid 140220548773632] [client 67.78.97.71:62452]   File "/usr/local/lib/python3.5/dist-packages/flask/app.py", line 1641, in full_dispatch_request
[Thu Nov 03 17:13:46.635213 2016] [wsgi:error] [pid 17408:tid 140220548773632] [client 67.78.97.71:62452]     rv = self.handle_user_exception(e)
[Thu Nov 03 17:13:46.635218 2016] [wsgi:error] [pid 17408:tid 140220548773632] [client 67.78.97.71:62452]   File "/usr/local/lib/python3.5/dist-packages/flask/app.py", line 1544, in handle_user_exception
[Thu Nov 03 17:13:46.635224 2016] [wsgi:error] [pid 17408:tid 140220548773632] [client 67.78.97.71:62452]     reraise(exc_type, exc_value, tb)
[Thu Nov 03 17:13:46.635230 2016] [wsgi:error] [pid 17408:tid 140220548773632] [client 67.78.97.71:62452]   File "/usr/local/lib/python3.5/dist-packages/flask/_compat.py", line 33, in reraise
[Thu Nov 03 17:13:46.635236 2016] [wsgi:error] [pid 17408:tid 140220548773632] [client 67.78.97.71:62452]     raise value
[Thu Nov 03 17:13:46.635241 2016] [wsgi:error] [pid 17408:tid 140220548773632] [client 67.78.97.71:62452]   File "/usr/local/lib/python3.5/dist-packages/flask/app.py", line 1639, in full_dispatch_request
[Thu Nov 03 17:13:46.635247 2016] [wsgi:error] [pid 17408:tid 140220548773632] [client 67.78.97.71:62452]     rv = self.dispatch_request()
[Thu Nov 03 17:13:46.635253 2016] [wsgi:error] [pid 17408:tid 140220548773632] [client 67.78.97.71:62452]   File "/usr/local/lib/python3.5/dist-packages/flask/app.py", line 1625, in dispatch_request
[Thu Nov 03 17:13:46.635259 2016] [wsgi:error] [pid 17408:tid 140220548773632] [client 67.78.97.71:62452]     return self.view_functions[rule.endpoint](**req.view_args)
[Thu Nov 03 17:13:46.635265 2016] [wsgi:error] [pid 17408:tid 140220548773632] [client 67.78.97.71:62452]   File "/var/www/cs373f-idb/app/app.py", line 184, in api_games_offset
[Thu Nov 03 17:13:46.635270 2016] [wsgi:error] [pid 17408:tid 140220548773632] [client 67.78.97.71:62452]     new_count = 25*int(offset)
[Thu Nov 03 17:13:46.635279 2016] [wsgi:error] [pid 17408:tid 140220548773632] [client 67.78.97.71:62452] ValueError: invalid literal for int() with base 10: '1 Failed to load resource: net::ERR_EMPTY_RESPONSE'
[Thu Nov 03 17:13:46.635332 2016] [wsgi:error] [pid 17408:tid 140220548773632] [client 67.78.97.71:62452] 
